Workbook

Sheet About
A1: Vehicle & Heavy Equipment Import Study — Method Demo
A2: Illustrative workbook. ALL DATA IS FICTIONAL: importer names, declarations and volumes were generated to demonstrate the method.
A4: What this workbook shows
A5: How raw customs import declarations are turned into a market-sizing and importer ranking for a RoRo / PCTC carrier, US East Coast origin only.
A7: Sheets
A8: Parameters — weight cut-off (15,000 kg/unit), HS headings per segment, list of US East Coast ports.
A9: Raw_Data — fictional declaration lines (navy headers) + calculated helper columns (teal headers).
A10: Name_Map — unifies spelling variants of the same importer before ranking.
A11: Ranking_Vehicles / Ranking_HH — Top 10 importers per segment; pick a country in the yellow cell.
A12: Summary — units by country and segment, US East Coast vs all origins, with chart.
A14: Method, step by step
A15: 1. Normalize importer names (Name_Map) so 'ANDES MOTOR GROUP SA' and 'Andes Motor Group S.A.' count as one company.
... A23: Navy header = source data | Teal header = calculated column (formula) | Yellow cell = selector you can change | Blue text = editable parameter

Sheet Parameters
A1: Parameters
A3: Weight cut-off (kg per unit) | B3: 15000 | C3: Vehicles ≤ cut-off; H&H > cut-off
A5: Vehicle HS headings | C5: H&H HS headings | E5: US East Coast ports | G5: HS heading | H5: Description
A6: 8703 | C6: 8701 | E6: Baltimore | G6: 8703 | H6: Passenger cars
A7: 8704 | C7: 8702 | E7: Brunswick | G7: 8704 | H7: Goods vehicles (trucks)
C8: 8704 | E8: Jacksonville | G8: 8701 | H8: Tractors
C9: 8705 | E9: Charleston | G9: 8702 | H9: Buses
C10: 8426 | E10: Savannah | G10: 8705 | H10: Special-purpose vehicles
C11: 8427 | E11: Davisville | G11: 8426 | H11: Cranes
C12: 8429 | E12: Newark | G12: 8427 | H12: Forklift trucks
C13: 8430 | E13: Philadelphia | G13: 8429 | H13: Bulldozers / excavators / loaders
C14: 8433 | G14: 8430 | H14: Other earthmoving / drilling machinery
G15: 8433 | H15: Harvesting machinery

Sheet Name_Map
A1: Importer name as declared | B1: Normalized importer
A2: ALTIPLANO TRUCKS SAC | B2: Altiplano Trucks S.A.C.
A3: ANDES MOTOR GROUP SA | B3: Andes Motor Group S.A.
A4: ANTILLAS CARGO LOGISTICS SRL | B4: Antillas Cargo Logistics S.R.L.
A5: ATACAMA EQUIPOS MINEROS SA | B5: Atacama Equipos Mineros S.A.
A6: AUSTRAL TRUCK CENTER SPA | B6: Austral Truck Center SpA
A7: AUTONORTE DISTRIBUCIONES SAS | B7: Autonorte Distribuciones S.A.S.
A8: Altiplano Trucks S.A.C. | B8: Altiplano Trucks S.A.C.
A9: Altiplano Trucks S.A.C. | B9: Altiplano Trucks S.A.C.
A10: Altiplano Trucks SAC | B10: Altiplano Trucks S.A.C.
A11: Andes Motor Group S.A. | B11: Andes Motor Group S.A.
A12: Andes Motor Group S.A. | B12: Andes Motor Group S.A.
... A102: Transcargo Pesados SAS | B102: Transcargo Pesados S.A.S.

Sheet Summary
A1: Market size by country — units (fictional data)
A3: Country | B3: Vehicles — US East Coast | C3: Vehicles — all origins | D3: Vehicles — EC share | E3: H&H — US East Coast | F3: H&H — all origins | G3: H&H — EC share
A4: Chile | B4: =SUMIFS(Raw_Data!$F$2:$F$307,Raw_Data!$C$2:$C$307,A4,Raw_Data!$O$2:$O$307,"Vehicles",Raw_Data!$N$2:$N$307,"Yes") -> 361 | C4: =SUMIFS(Raw_Data!$F$2:$F$307,Raw_Data!$C$2:$C$307,A4,Raw_Data!$O$2:$O$307,"Vehicles") -> 623 | D4: =IF(C4>0,B4/C4,0) -> 0.57945425 | E4: =SUMIFS(Raw_Data!$F$2:$F$307,Raw_Data!$C$2:$C$307,A4,Raw_Data!$O$2:$O$307,"H&H",Raw_Data!$N$2:$N$307,"Yes") -> 17 | F4: =SUMIFS(Raw_Data!$F$2:$F$307,Raw_Data!$C$2:$C$307,A4,Raw_Data!$O$2:$O$307,"H&H") -> 30 | G4: =IF(F4>0,E4/F4,0) -> 0.56666667
A5: Colombia | B5: =SUMIFS(Raw_Data!$F$2:$F$307,Raw_Data!$C$2:$C$307,A5,Raw_Data!$O$2:$O$307,"Vehicles",Raw_Data!$N$2:$N$307,"Yes") -> 400 | C5: =SUMIFS(Raw_Data!$F$2:$F$307,Raw_Data!$C$2:$C$307,A5,Raw_Data!$O$2:$O$307,"Vehicles") -> 564 | D5: =IF(C5>0,B5/C5,0) -> 0.70921986 | E5: =SUMIFS(Raw_Data!$F$2:$F$307,Raw_Data!$C$2:$C$307,A5,Raw_Data!$O$2:$O$307,"H&H",Raw_Data!$N$2:$N$307,"Yes") -> 14 | F5: =SUMIFS(Raw_Data!$F$2:$F$307,Raw_Data!$C$2:$C$307,A5,Raw_Data!$O$2:$O$307,"H&H") -> 49 | G5: =IF(F5>0,E5/F5,0) -> 0.28571429
A6: Peru | B6: =SUMIFS(Raw_Data!$F$2:$F$307,Raw_Data!$C$2:$C$307,A6,Raw_Data!$O$2:$O$307,"Vehicles",Raw_Data!$N$2:$N$307,"Yes") -> 429 | C6: =SUMIFS(Raw_Data!$F$2:$F$307,Raw_Data!$C$2:$C$307,A6,Raw_Data!$O$2:$O$307,"Vehicles") -> 744 | D6: =IF(C6>0,B6/C6,0) -> 0.5766129 | E6: =SUMIFS(Raw_Data!$F$2:$F$307,Raw_Data!$C$2:$C$307,A6,Raw_Data!$O$2:$O$307,"H&H",Raw_Data!$N$2:$N$307,"Yes") -> 13 | F6: =SUMIFS(Raw_Data!$F$2:$F$307,Raw_Data!$C$2:$C$307,A6,Raw_Data!$O$2:$O$307,"H&H") -> 30 | G6: =IF(F6>0,E6/F6,0) -> 0.43333333
A7: Ecuador | B7: =SUMIFS(Raw_Data!$F$2:$F$307,Raw_Data!$C$2:$C$307,A7,Raw_Data!$O$2:$O$307,"Vehicles",Raw_Data!$N$2:$N$307,"Yes") -> 414 | C7: =SUMIFS(Raw_Data!$F$2:$F$307,Raw_Data!$C$2:$C$307,A7,Raw_Data!$O$2:$O$307,"Vehicles") -> 600 | D7: =IF(C7>0,B7/C7,0) -> 0.69 | E7: =SUMIFS(Raw_Data!$F$2:$F$307,Raw_Data!$C$2:$C$307,A7,Raw_Data!$O$2:$O$307,"H&H",Raw_Data!$N$2:$N$307,"Yes") -> 20 | F7: =SUMIFS(Raw_Data!$F$2:$F$307,Raw_Data!$C$2:$C$307,A7,Raw_Data!$O$2:$O$307,"H&H") -> 41 | G7: =IF(F7>0,E7/F7,0) -> 0.48780488
A8: Dominican Republic | B8: =SUMIFS(Raw_Data!$F$2:$F$307,Raw_Data!$C$2:$C$307,A8,Raw_Data!$O$2:$O$307,"Vehicles",Raw_Data!$N$2:$N$307,"Yes") -> 440 | C8: =SUMIFS(Raw_Data!$F$2:$F$307,Raw_Data!$C$2:$C$307,A8,Raw_Data!$O$2:$O$307,"Vehicles") -> 674 | D8: =IF(C8>0,B8/C8,0) -> 0.65281899 | E8: =SUMIFS(Raw_Data!$F$2:$F$307,Raw_Data!$C$2:$C$307,A8,Raw_Data!$O$2:$O$307,"H&H",Raw_Data!$N$2:$N$307,"Yes") -> 28 | F8: =SUMIFS(Raw_Data!$F$2:$F$307,Raw_Data!$C$2:$C$307,A8,Raw_Data!$O$2:$O$307,"H&H") -> 46 | G8: =IF(F8>0,E8/F8,0) -> 0.60869565
A9: Panama | B9: =SUMIFS(Raw_Data!$F$2:$F$307,Raw_Data!$C$2:$C$307,A9,Raw_Data!$O$2:$O$307,"Vehicles",Raw_Data!$N$2:$N$307,"Yes") -> 394 | C9: =SUMIFS(Raw_Data!$F$2:$F$307,Raw_Data!$C$2:$C$307,A9,Raw_Data!$O$2:$O$307,"Vehicles") -> 654 | D9: =IF(C9>0,B9/C9,0) -> 0.60244648 | E9: =SUMIFS(Raw_Data!$F$2:$F$307,Raw_Data!$C$2:$C$307,A9,Raw_Data!$O$2:$O$307,"H&H",Raw_Data!$N$2:$N$307,"Yes") -> 33 | F9: =SUMIFS(Raw_Data!$F$2:$F$307,Raw_Data!$C$2:$C$307,A9,Raw_Data!$O$2:$O$307,"H&H") -> 40 | G9: =IF(F9>0,E9/F9,0) -> 0.825
A10: Total | B10: =SUM(B4:B9) -> 2438 | C10: =SUM(C4:C9) -> 3859 | D10: =IF(C10>0,B10/C10,0) -> 0.63176989 | E10: =SUM(E4:E9) -> 125 | F10: =SUM(F4:F9) -> 236 | G10: =IF(F10>0,E10/F10,0) -> 0.52966102
A11: Note: Vehicles and H&H use different units of scale (H&H units are much heavier); compare within each segment.

Sheet Raw_Data
A1: Declaration No | B1: Date | C1: Country | D1: Importer (as declared) | E1: HS heading | F1: Quantity (units) | G1: Gross weight (kg) | H1: Port of loading | I1: HS description | J1: Importer (normalized) | K1: Unit weight (kg) | L1: Weight check | M1: Corrected unit weight (kg) | N1: US East Coast? | O1: Segment | P1: Corrected gross weight (kg)
A2: CL-25-00015 | B2: 45658 | C2: Chile | D2: Andes Motor Group S.A. | E2: 8703 | F2: 21 | G2: 34512 | H2: Philadelphia | I2: =IFERROR(VLOOKUP(E2,Parameters!$G$6:$H$15,2,FALSE()),"") -> Passenger cars | J2: =IFERROR(INDEX(Name_Map!$B$2:$B$102,MATCH(D2,Name_Map!$A$2:$A$102,0)),D2) -> Andes Motor Group S.A. | K2: =IF(F2>0,G2/F2,0) -> 1643.4286 | L2: =IF(AND(COUNTIFS($A$2:$A$307,A2,$E$2:$E$307,E2)>1,COUNTIFS($A$2:$A$307,A2,$E$2:$E$307,E2,$G$2:$G$307,G2)=COUNTIFS($A$2:$A$307,A2,$E$2:$E$307,E2)),"CHECK","OK") -> OK | M2: =IF(L2="CHECK",G2/SUMIFS($F$2:$F$307,$A$2:$A$307,A2,$E$2:$E$307,E2),K2) -> 1643.4286 | N2: =IF(COUNTIF(Parameters!$E$6:$E$13,H2)>0,"Yes","No") -> Yes | O2: =IF(M2<=Parameters!$B$3,IF(COUNTIF(Parameters!$A$6:$A$7,E2)>0,"Vehicles","Out of scope"),IF(COUNTIF(Parameters!$C$6:$C$14,E2)>0,"H&H","Out of scope")) -> Vehicles | P2: =M2*F2 -> 34512
A3: PA-25-00016 | B3: 45659 | C3: Panama | D3: CANAL AUTOS SA | E3: 8704 | F3: 36 | G3: 204293 | H3: Yokohama | I3: =IFERROR(VLOOKUP(E3,Parameters!$G$6:$H$15,2,FALSE()),"") -> Goods vehicles (trucks) | J3: =IFERROR(INDEX(Name_Map!$B$2:$B$102,MATCH(D3,Name_Map!$A$2:$A$102,0)),D3) -> Canal Autos S.A. | K3: =IF(F3>0,G3/F3,0) -> 5674.8056 | L3: =IF(AND(COUNTIFS($A$2:$A$307,A3,$E$2:$E$307,E3)>1,COUNTIFS($A$2:$A$307,A3,$E$2:$E$307,E3,$G$2:$G$307,G3)=COUNTIFS($A$2:$A$307,A3,$E$2:$E$307,E3)),"CHECK","OK") -> OK | M3: =IF(L3="CHECK",G3/SUMIFS($F$2:$F$307,$A$2:$A$307,A3,$E$2:$E$307,E3),K3) -> 5674.8056 | N3: =IF(COUNTIF(Parameters!$E$6:$E$13,H3)>0,"Yes","No") -> No | O3: =IF(M3<=Parameters!$B$3,IF(COUNTIF(Parameters!$A$6:$A$7,E3)>0,"Vehicles","Out of scope"),IF(COUNTIF(Parameters!$C$6:$C$14,E3)>0,"H&H","Out of scope")) -> Vehicles | P3: =M3*F3 -> 204293
A4: PA-25-00016 | B4: 45659 | C4: Panama | D4: Canal Autos S.A. | E4: 8703 | F4: 31 | G4: 57622 | H4: Yokohama | I4: =IFERROR(VLOOKUP(E4,Parameters!$G$6:$H$15,2,FALSE()),"") -> Passenger cars | J4: =IFERROR(INDEX(Name_Map!$B$2:$B$102,MATCH(D4,Name_Map!$A$2:$A$102,0)),D4) -> Canal Autos S.A. | K4: =IF(F4>0,G4/F4,0) -> 1858.7742 | L4: =IF(AND(COUNTIFS($A$2:$A$307,A4,$E$2:$E$307,E4)>1,COUNTIFS($A$2:$A$307,A4,$E$2:$E$307,E4,$G$2:$G$307,G4)=COUNTIFS($A$2:$A$307,A4,$E$2:$E$307,E4)),"CHECK","OK") -> OK | M4: =IF(L4="CHECK",G4/SUMIFS($F$2:$F$307,$A$2:$A$307,A4,$E$2:$E$307,E4),K4) -> 1858.7742 | N4: =IF(COUNTIF(Parameters!$E$6:$E$13,H4)>0,"Yes","No") -> No | O4: =IF(M4<=Parameters!$B$3,IF(COUNTIF(Parameters!$A$6:$A$7,E4)>0,"Vehicles","Out of scope"),IF(COUNTIF(Parameters!$C$6:$C$14,E4)>0,"H&H","Out of scope")) -> Vehicles | P4: =M4*F4 -> 57622
A5: CL-25-00023 | B5: 45665 | C5: Chile | D5: Cordillera Maquinarias SpA | E5: 8429 | F5: 4 | G5: 167149 | H5: Bremerhaven | I5: =IFERROR(VLOOKUP(E5,Parameters!$G$6:$H$15,2,FALSE()),"") -> Bulldozers / excavators / loaders | J5: =IFERROR(INDEX(Name_Map!$B$2:$B$102,MATCH(D5,Name_Map!$A$2:$A$102,0)),D5) -> Cordillera Maquinarias SpA | K5: =IF(F5>0,G5/F5,0) -> 41787.25 | L5: =IF(AND(COUNTIFS($A$2:$A$307,A5,$E$2:$E$307,E5)>1,COUNTIFS($A$2:$A$307,A5,$E$2:$E$307,E5,$G$2:$G$307,G5)=COUNTIFS($A$2:$A$307,A5,$E$2:$E$307,E5)),"CHECK","OK") -> OK | M5: =IF(L5="CHECK",G5/SUMIFS($F$2:$F$307,$A$2:$A$307,A5,$E$2:$E$307,E5),K5) -> 41787.25 | N5: =IF(COUNTIF(Parameters!$E$6:$E$13,H5)>0,"Yes","No") -> No | O5: =IF(M5<=Parameters!$B$3,IF(COUNTIF(Parameters!$A$6:$A$7,E5)>0,"Vehicles","Out of scope"),IF(COUNTIF(Parameters!$C$6:$C$14,E5)>0,"H&H","Out of scope")) -> H&H | P5: =M5*F5 -> 167149
A6: PA-25-00005 | B6: 45665 | C6: Panama | D6: CANAL AUTOS SA | E6: 8704 | F6: 14 | G6: 50999 | H6: Bremerhaven | I6: =IFERROR(VLOOKUP(E6,Parameters!$G$6:$H$15,2,FALSE()),"") -> Goods vehicles (trucks) | J6: =IFERROR(INDEX(Name_Map!$B$2:$B$102,MATCH(D6,Name_Map!$A$2:$A$102,0)),D6) -> Canal Autos S.A. | K6: =IF(F6>0,G6/F6,0) -> 3642.7857 | L6: =IF(AND(COUNTIFS($A$2:$A$307,A6,$E$2:$E$307,E6)>1,COUNTIFS($A$2:$A$307,A6,$E$2:$E$307,E6,$G$2:$G$307,G6)=COUNTIFS($A$2:$A$307,A6,$E$2:$E$307,E6)),"CHECK","OK") -> OK | M6: =IF(L6="CHECK",G6/SUMIFS($F$2:$F$307,$A$2:$A$307,A6,$E$2:$E$307,E6),K6) -> 3642.7857 | N6: =IF(COUNTIF(Parameters!$E$6:$E$13,H6)>0,"Yes","No") -> No | O6: =IF(M6<=Parameters!$B$3,IF(COUNTIF(Parameters!$A$6:$A$7,E6)>0,"Vehicles","Out of scope"),IF(COUNTIF(Parameters!$C$6:$C$14,E6)>0,"H&H","Out of scope")) -> Vehicles | P6: =M6*F6 -> 50999
A7: PA-25-00005 | B7: 45665 | C7: Panama | D7: Canal Autos S.A. | E7: 8703 | F7: 29 | G7: 63996 | H7: Bremerhaven | I7: =IFERROR(VLOOKUP(E7,Parameters!$G$6:$H$15,2,FALSE()),"") -> Passenger cars | J7: =IFERROR(INDEX(Name_Map!$B$2:$B$102,MATCH(D7,Name_Map!$A$2:$A$102,0)),D7) -> Canal Autos S.A. | K7: =IF(F7>0,G7/F7,0) -> 2206.7586 | L7: =IF(AND(COUNTIFS($A$2:$A$307,A7,$E$2:$E$307,E7)>1,COUNTIFS($A$2:$A$307,A7,$E$2:$E$307,E7,$G$2:$G$307,G7)=COUNTIFS($A$2:$A$307,A7,$E$2:$E$307,E7)),"CHECK","OK") -> OK | M7: =IF(L7="CHECK",G7/SUMIFS($F$2:$F$307,$A$2:$A$307,A7,$E$2:$E$307,E7),K7) -> 2206.7586 | N7: =IF(COUNTIF(Parameters!$E$6:$E$13,H7)>0,"Yes","No") -> No | O7: =IF(M7<=Parameters!$B$3,IF(COUNTIF(Parameters!$A$6:$A$7,E7)>0,"Vehicles","Out of scope"),IF(COUNTIF(Parameters!$C$6:$C$14,E7)>0,"H&H","Out of scope")) -> Vehicles | P7: =M7*F7 -> 63996
A8: CO-25-00010 | B8: 45670 | C8: Colombia | D8: BOGOTA CAR IMPORT SAS | E8: 8703 | F8: 28 | G8: 68381 | H8: Philadelphia | I8: =IFERROR(VLOOKUP(E8,Parameters!$G$6:$H$15,2,FALSE()),"") -> Passenger cars | J8: =IFERROR(INDEX(Name_Map!$B$2:$B$102,MATCH(D8,Name_Map!$A$2:$A$102,0)),D8) -> Bogota Car Import S.A.S. | K8: =IF(F8>0,G8/F8,0) -> 2442.1786 | L8: =IF(AND(COUNTIFS($A$2:$A$307,A8,$E$2:$E$307,E8)>1,COUNTIFS($A$2:$A$307,A8,$E$2:$E$307,E8,$G$2:$G$307,G8)=COUNTIFS($A$2:$A$307,A8,$E$2:$E$307,E8)),"CHECK","OK") -> OK | M8: =IF(L8="CHECK",G8/SUMIFS($F$2:$F$307,$A$2:$A$307,A8,$E$2:$E$307,E8),K8) -> 2442.1786 | N8: =IF(COUNTIF(Parameters!$E$6:$E$13,H8)>0,"Yes","No") -> Yes | O8: =IF(M8<=Parameters!$B$3,IF(COUNTIF(Parameters!$A$6:$A$7,E8)>0,"Vehicles","Out of scope"),IF(COUNTIF(Parameters!$C$6:$C$14,E8)>0,"H&H","Out of scope")) -> Vehicles | P8: =M8*F8 -> 68381
A9: CL-25-00034 | B9: 45676 | C9: Chile | D9: Austral Truck Center SpA | E9: 8429 | F9: 2 | G9: 23979 | H9: Shanghai | I9: =IFERROR(VLOOKUP(E9,Parameters!$G$6:$H$15,2,FALSE()),"") -> Bulldozers / excavators / loaders | J9: =IFERROR(INDEX(Name_Map!$B$2:$B$102,MATCH(D9,Name_Map!$A$2:$A$102,0)),D9) -> Austral Truck Center SpA | K9: =IF(F9>0,G9/F9,0) -> 11989.5 | L9: =IF(AND(COUNTIFS($A$2:$A$307,A9,$E$2:$E$307,E9)>1,COUNTIFS($A$2:$A$307,A9,$E$2:$E$307,E9,$G$2:$G$307,G9)=COUNTIFS($A$2:$A$307,A9,$E$2:$E$307,E9)),"CHECK","OK") -> OK | M9: =IF(L9="CHECK",G9/SUMIFS($F$2:$F$307,$A$2:$A$307,A9,$E$2:$E$307,E9),K9) -> 11989.5 | N9: =IF(COUNTIF(Parameters!$E$6:$E$13,H9)>0,"Yes","No") -> No | O9: =IF(M9<=Parameters!$B$3,IF(COUNTIF(Parameters!$A$6:$A$7,E9)>0,"Vehicles","Out of scope"),IF(COUNTIF(Parameters!$C$6:$C$14,E9)>0,"H&H","Out of scope")) -> Out of scope | P9: =M9*F9 -> 23979
A10: EC-25-00029 | B10: 45677 | C10: Ecuador | D10: Equinoccio Maquinaria S.A. | E10: 8429 | F10: 2 | G10: 121833 | H10: Bremerhaven | I10: =IFERROR(VLOOKUP(E10,Parameters!$G$6:$H$15,2,FALSE()),"") -> Bulldozers / excavators / loaders | J10: =IFERROR(INDEX(Name_Map!$B$2:$B$102,MATCH(D10,Name_Map!$A$2:$A$102,0)),D10) -> Equinoccio Maquinaria S.A. | K10: =IF(F10>0,G10/F10,0) -> 60916.5 | L10: =IF(AND(COUNTIFS($A$2:$A$307,A10,$E$2:$E$307,E10)>1,COUNTIFS($A$2:$A$307,A10,$E$2:$E$307,E10,$G$2:$G$307,G10)=COUNTIFS($A$2:$A$307,A10,$E$2:$E$307,E10)),"CHECK","OK") -> OK | M10: =IF(L10="CHECK",G10/SUMIFS($F$2:$F$307,$A$2:$A$307,A10,$E$2:$E$307,E10),K10) -> 60916.5 | N10: =IF(COUNTIF(Parameters!$E$6:$E$13,H10)>0,"Yes","No") -> No | O10: =IF(M10<=Parameters!$B$3,IF(COUNTIF(Parameters!$A$6:$A$7,E10)>0,"Vehicles","Out of scope"),IF(COUNTIF(Parameters!$C$6:$C$14,E10)>0,"H&H","Out of scope")) -> H&H | P10: =M10*F10 -> 121833
A11: EC-25-00029 | B11: 45677 | C11: Ecuador | D11: Equinoccio Maquinaria S.A. | E11: 8429 | F11: 1 | G11: 59882 | H11: Bremerhaven | I11: =IFERROR(VLOOKUP(E11,Parameters!$G$6:$H$15,2,FALSE()),"") -> Bulldozers / excavators / loaders | J11: =IFERROR(INDEX(Name_Map!$B$2:$B$102,MATCH(D11,Name_Map!$A$2:$A$102,0)),D11) -> Equinoccio Maquinaria S.A. | K11: =IF(F11>0,G11/F11,0) -> 59882 | L11: =IF(AND(COUNTIFS($A$2:$A$307,A11,$E$2:$E$307,E11)>1,COUNTIFS($A$2:$A$307,A11,$E$2:$E$307,E11,$G$2:$G$307,G11)=COUNTIFS($A$2:$A$307,A11,$E$2:$E$307,E11)),"CHECK","OK") -> OK | M11: =IF(L11="CHECK",G11/SUMIFS($F$2:$F$307,$A$2:$A$307,A11,$E$2:$E$307,E11),K11) -> 59882 | N11: =IF(COUNTIF(Parameters!$E$6:$E$13,H11)>0,"Yes","No") -> No | O11: =IF(M11<=Parameters!$B$3,IF(COUNTIF(Parameters!$A$6:$A$7,E11)>0,"Vehicles","Out of scope"),IF(COUNTIF(Parameters!$C$6:$C$14,E11)>0,"H&H","Out of scope")) -> H&H | P11: =M11*F11 -> 59882
A12: PA-25-00003 | B12: 45677 | C12: Panama | D12: Canal Autos S.A. | E12: 8703 | F12: 36 | G12: 80045 | H12: Brunswick | I12: =IFERROR(VLOOKUP(E12,Parameters!$G$6:$H$15,2,FALSE()),"") -> Passenger cars | J12: =IFERROR(INDEX(Name_Map!$B$2:$B$102,MATCH(D12,Name_Map!$A$2:$A$102,0)),D12) -> Canal Autos S.A. | K12: =IF(F12>0,G12/F12,0) -> 2223.4722 | L12: =IF(AND(COUNTIFS($A$2:$A$307,A12,$E$2:$E$307,E12)>1,COUNTIFS($A$2:$A$307,A12,$E$2:$E$307,E12,$G$2:$G$307,G12)=COUNTIFS($A$2:$A$307,A12,$E$2:$E$307,E12)),"CHECK","OK") -> OK | M12: =IF(L12="CHECK",G12/SUMIFS($F$2:$F$307,$A$2:$A$307,A12,$E$2:$E$307,E12),K12) -> 2223.4722 | N12: =IF(COUNTIF(Parameters!$E$6:$E$13,H12)>0,"Yes","No") -> Yes | O12: =IF(M12<=Parameters!$B$3,IF(COUNTIF(Parameters!$A$6:$A$7,E12)>0,"Vehicles","Out of scope"),IF(COUNTIF(Parameters!$C$6:$C$14,E12)>0,"H&H","Out of scope")) -> Vehicles | P12: =M12*F12 -> 80045
A13: EC-25-00035 | B13: 45682 | C13: Ecuador | D13: Equinoccio Maquinaria S.A. | E13: 8429 | F13: 1 | G13: 53204 | H13: Philadelphia | I13: =IFERROR(VLOOKUP(E13,Parameters!$G$6:$H$15,2,FALSE()),"") -> Bulldozers / excavators / loaders | J13: =IFERROR(INDEX(Name_Map!$B$2:$B$102,MATCH(D13,Name_Map!$A$2:$A$102,0)),D13) -> Equinoccio Maquinaria S.A. | K13: =IF(F13>0,G13/F13,0) -> 53204 | L13: =IF(AND(COUNTIFS($A$2:$A$307,A13,$E$2:$E$307,E13)>1,COUNTIFS($A$2:$A$307,A13,$E$2:$E$307,E13,$G$2:$G$307,G13)=COUNTIFS($A$2:$A$307,A13,$E$2:$E$307,E13)),"CHECK","OK") -> OK | M13: =IF(L13="CHECK",G13/SUMIFS($F$2:$F$307,$A$2:$A$307,A13,$E$2:$E$307,E13),K13) -> 53204 | N13: =IF(COUNTIF(Parameters!$E$6:$E$13,H13)>0,"Yes","No") -> Yes | O13: =IF(M13<=Parameters!$B$3,IF(COUNTIF(Parameters!$A$6:$A$7,E13)>0,"Vehicles","Out of scope"),IF(COUNTIF(Parameters!$C$6:$C$14,E13)>0,"H&H","Out of scope")) -> H&H | P13: =M13*F13 -> 53204
... A307: DO-25-00032 | B307: 46019 | C307: Dominican Republic | D307: Antillas Cargo Logistics S.R.L. | E307: 8429 | F307: 4 | G307: 107464 | H307: Charleston | I307: =IFERROR(VLOOKUP(E307,Parameters!$G$6:$H$15,2,FALSE()),"") -> Bulldozers / excavators / loaders | J307: =IFERROR(INDEX(Name_Map!$B$2:$B$102,MATCH(D307,Name_Map!$A$2:$A$102,0)),D307) -> Antillas Cargo Logistics S.R.L. | K307: =IF(F307>0,G307/F307,0) -> 26866 | L307: =IF(AND(COUNTIFS($A$2:$A$307,A307,$E$2:$E$307,E307)>1,COUNTIFS($A$2:$A$307,A307,$E$2:$E$307,E307,$G$2:$G$307,G307)=COUNTIFS($A$2:$A$307,A307,$E$2:$E$307,E307)),"CHECK","OK") -> OK | M307: =IF(L307="CHECK",G307/SUMIFS($F$2:$F$307,$A$2:$A$307,A307,$E$2:$E$307,E307),K307) -> 26866 | N307: =IF(COUNTIF(Parameters!$E$6:$E$13,H307)>0,"Yes","No") -> Yes | O307: =IF(M307<=Parameters!$B$3,IF(COUNTIF(Parameters!$A$6:$A$7,E307)>0,"Vehicles","Out of scope"),IF(COUNTIF(Parameters!$C$6:$C$14,E307)>0,"H&H","Out of scope")) -> H&H | P307: =M307*F307 -> 107464

Sheet Ranking_Vehicles
A1: Top 10 importers — Passenger vehicles & light commercial (≤ 15 t/unit)
A2: US East Coast origin only. Fictional data.
A3: Country: | B3: All countries
H4: Calculation table (all importers)
A5: Rank | B5: Importer | C5: Units | D5: Weight (t) | E5: Market share | H5: Importer (all) | I5: Units | J5: Weight (t) | K5: Rank
A6: 1 | B6: =IFERROR(INDEX($H$6:$H$36,MATCH(A6,$K$6:$K$36,0)),"") -> Guayas Autos S.A. | C6: =IFERROR(INDEX($I$6:$I$36,MATCH(A6,$K$6:$K$36,0)),"") -> 267 | D6: =IFERROR(INDEX($J$6:$J$36,MATCH(A6,$K$6:$K$36,0)),"") -> 1100.062 | E6: =IF(C6="","",C6/$C$18) -> 0.109516 | H6: Altiplano Trucks S.A.C. | I6: =IF($B$3="All countries",SUMIFS(Raw_Data!$F$2:$F$307,Raw_Data!$J$2:$J$307,H6,Raw_Data!$O$2:$O$307,"Vehicles",Raw_Data!$N$2:$N$307,"Yes"),SUMIFS(Raw_Data!$F$2:$F$307,Raw_Data!$J$2:$J$307,H6,Raw_Data!$O$2:$O$307,"Vehicles",Raw_Data!$N$2:$N$307,"Yes",Raw_Data!$C$2:$C$307,$B$3)) -> 90 | J6: =IF($B$3="All countries",SUMIFS(Raw_Data!$P$2:$P$307,Raw_Data!$J$2:$J$307,H6,Raw_Data!$O$2:$O$307,"Vehicles",Raw_Data!$N$2:$N$307,"Yes"),SUMIFS(Raw_Data!$P$2:$P$307,Raw_Data!$J$2:$J$307,H6,Raw_Data!$O$2:$O$307,"Vehicles",Raw_Data!$N$2:$N$307,"Yes",Raw_Data!$C$2:$C$307,$B$3))/1000 -> 242.149 | K6: =IF(I6>0,RANK(I6,$I$6:$I$36)+COUNTIF($I$6:I6,I6)-1,"") -> 13
A7: 2 | B7: =IFERROR(INDEX($H$6:$H$36,MATCH(A7,$K$6:$K$36,0)),"") -> Quisqueya Motors S.R.L. | C7: =IFERROR(INDEX($I$6:$I$36,MATCH(A7,$K$6:$K$36,0)),"") -> 250 | D7: =IFERROR(INDEX($J$6:$J$36,MATCH(A7,$K$6:$K$36,0)),"") -> 709.753 | E7: =IF(C7="","",C7/$C$18) -> 0.10254307 | H7: Andes Motor Group S.A. | I7: =IF($B$3="All countries",SUMIFS(Raw_Data!$F$2:$F$307,Raw_Data!$J$2:$J$307,H7,Raw_Data!$O$2:$O$307,"Vehicles",Raw_Data!$N$2:$N$307,"Yes"),SUMIFS(Raw_Data!$F$2:$F$307,Raw_Data!$J$2:$J$307,H7,Raw_Data!$O$2:$O$307,"Vehicles",Raw_Data!$N$2:$N$307,"Yes",Raw_Data!$C$2:$C$307,$B$3)) -> 139 | J7: =IF($B$3="All countries",SUMIFS(Raw_Data!$P$2:$P$307,Raw_Data!$J$2:$J$307,H7,Raw_Data!$O$2:$O$307,"Vehicles",Raw_Data!$N$2:$N$307,"Yes"),SUMIFS(Raw_Data!$P$2:$P$307,Raw_Data!$J$2:$J$307,H7,Raw_Data!$O$2:$O$307,"Vehicles",Raw_Data!$N$2:$N$307,"Yes",Raw_Data!$C$2:$C$307,$B$3))/1000 -> 313.429 | K7: =IF(I7>0,RANK(I7,$I$6:$I$36)+COUNTIF($I$6:I7,I7)-1,"") -> 11
A8: 3 | B8: =IFERROR(INDEX($H$6:$H$36,MATCH(A8,$K$6:$K$36,0)),"") -> Canal Autos S.A. | C8: =IFERROR(INDEX($I$6:$I$36,MATCH(A8,$K$6:$K$36,0)),"") -> 233 | D8: =IFERROR(INDEX($J$6:$J$36,MATCH(A8,$K$6:$K$36,0)),"") -> 1088.169 | E8: =IF(C8="","",C8/$C$18) -> 0.095570139 | H8: Antillas Cargo Logistics S.R.L. | I8: =IF($B$3="All countries",SUMIFS(Raw_Data!$F$2:$F$307,Raw_Data!$J$2:$J$307,H8,Raw_Data!$O$2:$O$307,"Vehicles",Raw_Data!$N$2:$N$307,"Yes"),SUMIFS(Raw_Data!$F$2:$F$307,Raw_Data!$J$2:$J$307,H8,Raw_Data!$O$2:$O$307,"Vehicles",Raw_Data!$N$2:$N$307,"Yes",Raw_Data!$C$2:$C$307,$B$3)) -> 0 | J8: =IF($B$3="All countries",SUMIFS(Raw_Data!$P$2:$P$307,Raw_Data!$J$2:$J$307,H8,Raw_Data!$O$2:$O$307,"Vehicles",Raw_Data!$N$2:$N$307,"Yes"),SUMIFS(Raw_Data!$P$2:$P$307,Raw_Data!$J$2:$J$307,H8,Raw_Data!$O$2:$O$307,"Vehicles",Raw_Data!$N$2:$N$307,"Yes",Raw_Data!$C$2:$C$307,$B$3))/1000 -> 0 | K8: =IF(I8>0,RANK(I8,$I$6:$I$36)+COUNTIF($I$6:I8,I8)-1,"")
A9: 4 | B9: =IFERROR(INDEX($H$6:$H$36,MATCH(A9,$K$6:$K$36,0)),"") -> Santo Domingo Autos S.R.L. | C9: =IFERROR(INDEX($I$6:$I$36,MATCH(A9,$K$6:$K$36,0)),"") -> 190 | D9: =IFERROR(INDEX($J$6:$J$36,MATCH(A9,$K$6:$K$36,0)),"") -> 551.907 | E9: =IF(C9="","",C9/$C$18) -> 0.077932732 | H9: Atacama Equipos Mineros S.A. | I9: =IF($B$3="All countries",SUMIFS(Raw_Data!$F$2:$F$307,Raw_Data!$J$2:$J$307,H9,Raw_Data!$O$2:$O$307,"Vehicles",Raw_Data!$N$2:$N$307,"Yes"),SUMIFS(Raw_Data!$F$2:$F$307,Raw_Data!$J$2:$J$307,H9,Raw_Data!$O$2:$O$307,"Vehicles",Raw_Data!$N$2:$N$307,"Yes",Raw_Data!$C$2:$C$307,$B$3)) -> 0 | J9: =IF($B$3="All countries",SUMIFS(Raw_Data!$P$2:$P$307,Raw_Data!$J$2:$J$307,H9,Raw_Data!$O$2:$O$307,"Vehicles",Raw_Data!$N$2:$N$307,"Yes"),SUMIFS(Raw_Data!$P$2:$P$307,Raw_Data!$J$2:$J$307,H9,Raw_Data!$O$2:$O$307,"Vehicles",Raw_Data!$N$2:$N$307,"Yes",Raw_Data!$C$2:$C$307,$B$3))/1000 -> 0 | K9: =IF(I9>0,RANK(I9,$I$6:$I$36)+COUNTIF($I$6:I9,I9)-1,"")
A10: 5 | B10: =IFERROR(INDEX($H$6:$H$36,MATCH(A10,$K$6:$K$36,0)),"") -> Inca Automotriz S.A.C. | C10: =IFERROR(INDEX($I$6:$I$36,MATCH(A10,$K$6:$K$36,0)),"") -> 189 | D10: =IFERROR(INDEX($J$6:$J$36,MATCH(A10,$K$6:$K$36,0)),"") -> 494.672 | E10: =IF(C10="","",C10/$C$18) -> 0.077522559 | H10: Austral Truck Center SpA | I10: =IF($B$3="All countries",SUMIFS(Raw_Data!$F$2:$F$307,Raw_Data!$J$2:$J$307,H10,Raw_Data!$O$2:$O$307,"Vehicles",Raw_Data!$N$2:$N$307,"Yes"),SUMIFS(Raw_Data!$F$2:$F$307,Raw_Data!$J$2:$J$307,H10,Raw_Data!$O$2:$O$307,"Vehicles",Raw_Data!$N$2:$N$307,"Yes",Raw_Data!$C$2:$C$307,$B$3)) -> 144 | J10: =IF($B$3="All countries",SUMIFS(Raw_Data!$P$2:$P$307,Raw_Data!$J$2:$J$307,H10,Raw_Data!$O$2:$O$307,"Vehicles",Raw_Data!$N$2:$N$307,"Yes"),SUMIFS(Raw_Data!$P$2:$P$307,Raw_Data!$J$2:$J$307,H10,Raw_Data!$O$2:$O$307,"Vehicles",Raw_Data!$N$2:$N$307,"Yes",Raw_Data!$C$2:$C$307,$B$3))/1000 -> 399.748 | K10: =IF(I10>0,RANK(I10,$I$6:$I$36)+COUNTIF($I$6:I10,I10)-1,"") -> 9
A11: 6 | B11: =IFERROR(INDEX($H$6:$H$36,MATCH(A11,$K$6:$K$36,0)),"") -> Bogota Car Import S.A.S. | C11: =IFERROR(INDEX($I$6:$I$36,MATCH(A11,$K$6:$K$36,0)),"") -> 186 | D11: =IFERROR(INDEX($J$6:$J$36,MATCH(A11,$K$6:$K$36,0)),"") -> 684.364 | E11: =IF(C11="","",C11/$C$18) -> 0.076292043 | H11: Autonorte Distribuciones S.A.S. | I11: =IF($B$3="All countries",SUMIFS(Raw_Data!$F$2:$F$307,Raw_Data!$J$2:$J$307,H11,Raw_Data!$O$2:$O$307,"Vehicles",Raw_Data!$N$2:$N$307,"Yes"),SUMIFS(Raw_Data!$F$2:$F$307,Raw_Data!$J$2:$J$307,H11,Raw_Data!$O$2:$O$307,"Vehicles",Raw_Data!$N$2:$N$307,"Yes",Raw_Data!$C$2:$C$307,$B$3)) -> 128 | J11: =IF($B$3="All countries",SUMIFS(Raw_Data!$P$2:$P$307,Raw_Data!$J$2:$J$307,H11,Raw_Data!$O$2:$O$307,"Vehicles",Raw_Data!$N$2:$N$307,"Yes"),SUMIFS(Raw_Data!$P$2:$P$307,Raw_Data!$J$2:$J$307,H11,Raw_Data!$O$2:$O$307,"Vehicles",Raw_Data!$N$2:$N$307,"Yes",Raw_Data!$C$2:$C$307,$B$3))/1000 -> 326.645 | K11: =IF(I11>0,RANK(I11,$I$6:$I$36)+COUNTIF($I$6:I11,I11)-1,"") -> 12
A12: 7 | B12: =IFERROR(INDEX($H$6:$H$36,MATCH(A12,$K$6:$K$36,0)),"") -> Istmo Motors S.A. | C12: =IFERROR(INDEX($I$6:$I$36,MATCH(A12,$K$6:$K$36,0)),"") -> 161 | D12: =IFERROR(INDEX($J$6:$J$36,MATCH(A12,$K$6:$K$36,0)),"") -> 408.196 | E12: =IF(C12="","",C12/$C$18) -> 0.066037736 | H12: Bogota Car Import S.A.S. | I12: =IF($B$3="All countries",SUMIFS(Raw_Data!$F$2:$F$307,Raw_Data!$J$2:$J$307,H12,Raw_Data!$O$2:$O$307,"Vehicles",Raw_Data!$N$2:$N$307,"Yes"),SUMIFS(Raw_Data!$F$2:$F$307,Raw_Data!$J$2:$J$307,H12,Raw_Data!$O$2:$O$307,"Vehicles",Raw_Data!$N$2:$N$307,"Yes",Raw_Data!$C$2:$C$307,$B$3)) -> 186 | J12: =IF($B$3="All countries",SUMIFS(Raw_Data!$P$2:$P$307,Raw_Data!$J$2:$J$307,H12,Raw_Data!$O$2:$O$307,"Vehicles",Raw_Data!$N$2:$N$307,"Yes"),SUMIFS(Raw_Data!$P$2:$P$307,Raw_Data!$J$2:$J$307,H12,Raw_Data!$O$2:$O$307,"Vehicles",Raw_Data!$N$2:$N$307,"Yes",Raw_Data!$C$2:$C$307,$B$3))/1000 -> 684.364 | K12: =IF(I12>0,RANK(I12,$I$6:$I$36)+COUNTIF($I$6:I12,I12)-1,"") -> 6
A13: 8 | B13: =IFERROR(INDEX($H$6:$H$36,MATCH(A13,$K$6:$K$36,0)),"") -> Lima Car Import S.A.C. | C13: =IFERROR(INDEX($I$6:$I$36,MATCH(A13,$K$6:$K$36,0)),"") -> 150 | D13: =IFERROR(INDEX($J$6:$J$36,MATCH(A13,$K$6:$K$36,0)),"") -> 529.284 | E13: =IF(C13="","",C13/$C$18) -> 0.061525841 | H13: Canal Autos S.A. | I13: =IF($B$3="All countries",SUMIFS(Raw_Data!$F$2:$F$307,Raw_Data!$J$2:$J$307,H13,Raw_Data!$O$2:$O$307,"Vehicles",Raw_Data!$N$2:$N$307,"Yes"),SUMIFS(Raw_Data!$F$2:$F$307,Raw_Data!$J$2:$J$307,H13,Raw_Data!$O$2:$O$307,"Vehicles",Raw_Data!$N$2:$N$307,"Yes",Raw_Data!$C$2:$C$307,$B$3)) -> 233 | J13: =IF($B$3="All countries",SUMIFS(Raw_Data!$P$2:$P$307,Raw_Data!$J$2:$J$307,H13,Raw_Data!$O$2:$O$307,"Vehicles",Raw_Data!$N$2:$N$307,"Yes"),SUMIFS(Raw_Data!$P$2:$P$307,Raw_Data!$J$2:$J$307,H13,Raw_Data!$O$2:$O$307,"Vehicles",Raw_Data!$N$2:$N$307,"Yes",Raw_Data!$C$2:$C$307,$B$3))/1000 -> 1088.169 | K13: =IF(I13>0,RANK(I13,$I$6:$I$36)+COUNTIF($I$6:I13,I13)-1,"") -> 3
A14: 9 | B14: =IFERROR(INDEX($H$6:$H$36,MATCH(A14,$K$6:$K$36,0)),"") -> Austral Truck Center SpA | C14: =IFERROR(INDEX($I$6:$I$36,MATCH(A14,$K$6:$K$36,0)),"") -> 144 | D14: =IFERROR(INDEX($J$6:$J$36,MATCH(A14,$K$6:$K$36,0)),"") -> 399.748 | E14: =IF(C14="","",C14/$C$18) -> 0.059064807 | H14: Caribbean Freight Express S.R.L. | I14: =IF($B$3="All countries",SUMIFS(Raw_Data!$F$2:$F$307,Raw_Data!$J$2:$J$307,H14,Raw_Data!$O$2:$O$307,"Vehicles",Raw_Data!$N$2:$N$307,"Yes"),SUMIFS(Raw_Data!$F$2:$F$307,Raw_Data!$J$2:$J$307,H14,Raw_Data!$O$2:$O$307,"Vehicles",Raw_Data!$N$2:$N$307,"Yes",Raw_Data!$C$2:$C$307,$B$3)) -> 0 | J14: =IF($B$3="All countries",SUMIFS(Raw_Data!$P$2:$P$307,Raw_Data!$J$2:$J$307,H14,Raw_Data!$O$2:$O$307,"Vehicles",Raw_Data!$N$2:$N$307,"Yes"),SUMIFS(Raw_Data!$P$2:$P$307,Raw_Data!$J$2:$J$307,H14,Raw_Data!$O$2:$O$307,"Vehicles",Raw_Data!$N$2:$N$307,"Yes",Raw_Data!$C$2:$C$307,$B$3))/1000 -> 0 | K14: =IF(I14>0,RANK(I14,$I$6:$I$36)+COUNTIF($I$6:I14,I14)-1,"")
A15: 10 | B15: =IFERROR(INDEX($H$6:$H$36,MATCH(A15,$K$6:$K$36,0)),"") -> Ecuamotors Cia. Ltda. | C15: =IFERROR(INDEX($I$6:$I$36,MATCH(A15,$K$6:$K$36,0)),"") -> 140 | D15: =IFERROR(INDEX($J$6:$J$36,MATCH(A15,$K$6:$K$36,0)),"") -> 242.158 | E15: =IF(C15="","",C15/$C$18) -> 0.057424118 | H15: Caribe Motores S.A.S. | I15: =IF($B$3="All countries",SUMIFS(Raw_Data!$F$2:$F$307,Raw_Data!$J$2:$J$307,H15,Raw_Data!$O$2:$O$307,"Vehicles",Raw_Data!$N$2:$N$307,"Yes"),SUMIFS(Raw_Data!$F$2:$F$307,Raw_Data!$J$2:$J$307,H15,Raw_Data!$O$2:$O$307,"Vehicles",Raw_Data!$N$2:$N$307,"Yes",Raw_Data!$C$2:$C$307,$B$3)) -> 86 | J15: =IF($B$3="All countries",SUMIFS(Raw_Data!$P$2:$P$307,Raw_Data!$J$2:$J$307,H15,Raw_Data!$O$2:$O$307,"Vehicles",Raw_Data!$N$2:$N$307,"Yes"),SUMIFS(Raw_Data!$P$2:$P$307,Raw_Data!$J$2:$J$307,H15,Raw_Data!$O$2:$O$307,"Vehicles",Raw_Data!$N$2:$N$307,"Yes",Raw_Data!$C$2:$C$307,$B$3))/1000 -> 390.082 | K15: =IF(I15>0,RANK(I15,$I$6:$I$36)+COUNTIF($I$6:I15,I15)-1,"") -> 14
B16: Top 10 total | C16: =SUM(C6:C15) -> 1910 | E16: =IF($C$18>0,C16/$C$18,0) -> 0.78342904 | H16: Chiriqui Agro Machinery S.A. | I16: =IF($B$3="All countries",SUMIFS(Raw_Data!$F$2:$F$307,Raw_Data!$J$2:$J$307,H16,Raw_Data!$O$2:$O$307,"Vehicles",Raw_Data!$N$2:$N$307,"Yes"),SUMIFS(Raw_Data!$F$2:$F$307,Raw_Data!$J$2:$J$307,H16,Raw_Data!$O$2:$O$307,"Vehicles",Raw_Data!$N$2:$N$307,"Yes",Raw_Data!$C$2:$C$307,$B$3)) -> 0 | J16: =IF($B$3="All countries",SUMIFS(Raw_Data!$P$2:$P$307,Raw_Data!$J$2:$J$307,H16,Raw_Data!$O$2:$O$307,"Vehicles",Raw_Data!$N$2:$N$307,"Yes"),SUMIFS(Raw_Data!$P$2:$P$307,Raw_Data!$J$2:$J$307,H16,Raw_Data!$O$2:$O$307,"Vehicles",Raw_Data!$N$2:$N$307,"Yes",Raw_Data!$C$2:$C$307,$B$3))/1000 -> 0 | K16: =IF(I16>0,RANK(I16,$I$6:$I$36)+COUNTIF($I$6:I16,I16)-1,"")
B17: Rest of importers | C17: =C18-C16 -> 528 | E17: =IF($C$18>0,C17/$C$18,0) -> 0.21657096 | H17: Cibao Equipos S.R.L. | I17: =IF($B$3="All countries",SUMIFS(Raw_Data!$F$2:$F$307,Raw_Data!$J$2:$J$307,H17,Raw_Data!$O$2:$O$307,"Vehicles",Raw_Data!$N$2:$N$307,"Yes"),SUMIFS(Raw_Data!$F$2:$F$307,Raw_Data!$J$2:$J$307,H17,Raw_Data!$O$2:$O$307,"Vehicles",Raw_Data!$N$2:$N$307,"Yes",Raw_Data!$C$2:$C$307,$B$3)) -> 0 | J17: =IF($B$3="All countries",SUMIFS(Raw_Data!$P$2:$P$307,Raw_Data!$J$2:$J$307,H17,Raw_Data!$O$2:$O$307,"Vehicles",Raw_Data!$N$2:$N$307,"Yes"),SUMIFS(Raw_Data!$P$2:$P$307,Raw_Data!$J$2:$J$307,H17,Raw_Data!$O$2:$O$307,"Vehicles",Raw_Data!$N$2:$N$307,"Yes",Raw_Data!$C$2:$C$307,$B$3))/1000 -> 0 | K17: =IF(I17>0,RANK(I17,$I$6:$I$36)+COUNTIF($I$6:I17,I17)-1,"")
B18: Total market | C18: =SUM(I6:I36) -> 2438 | E18: =IF($C$18>0,1,0) -> 1 | H18: Colon Free Zone Traders S.A. | I18: =IF($B$3="All countries",SUMIFS(Raw_Data!$F$2:$F$307,Raw_Data!$J$2:$J$307,H18,Raw_Data!$O$2:$O$307,"Vehicles",Raw_Data!$N$2:$N$307,"Yes"),SUMIFS(Raw_Data!$F$2:$F$307,Raw_Data!$J$2:$J$307,H18,Raw_Data!$O$2:$O$307,"Vehicles",Raw_Data!$N$2:$N$307,"Yes",Raw_Data!$C$2:$C$307,$B$3)) -> 0 | J18: =IF($B$3="All countries",SUMIFS(Raw_Data!$P$2:$P$307,Raw_Data!$J$2:$J$307,H18,Raw_Data!$O$2:$O$307,"Vehicles",Raw_Data!$N$2:$N$307,"Yes"),SUMIFS(Raw_Data!$P$2:$P$307,Raw_Data!$J$2:$J$307,H18,Raw_Data!$O$2:$O$307,"Vehicles",Raw_Data!$N$2:$N$307,"Yes",Raw_Data!$C$2:$C$307,$B$3))/1000 -> 0 | K18: =IF(I18>0,RANK(I18,$I$6:$I$36)+COUNTIF($I$6:I18,I18)-1,"")
B19: Number of active importers | C19: =COUNTIF(I6:I36,">0") -> 16 | H19: Cordillera Maquinarias SpA | I19: =IF($B$3="All countries",SUMIFS(Raw_Data!$F$2:$F$307,Raw_Data!$J$2:$J$307,H19,Raw_Data!$O$2:$O$307,"Vehicles",Raw_Data!$N$2:$N$307,"Yes"),SUMIFS(Raw_Data!$F$2:$F$307,Raw_Data!$J$2:$J$307,H19,Raw_Data!$O$2:$O$307,"Vehicles",Raw_Data!$N$2:$N$307,"Yes",Raw_Data!$C$2:$C$307,$B$3)) -> 0 | J19: =IF($B$3="All countries",SUMIFS(Raw_Data!$P$2:$P$307,Raw_Data!$J$2:$J$307,H19,Raw_Data!$O$2:$O$307,"Vehicles",Raw_Data!$N$2:$N$307,"Yes"),SUMIFS(Raw_Data!$P$2:$P$307,Raw_Data!$J$2:$J$307,H19,Raw_Data!$O$2:$O$307,"Vehicles",Raw_Data!$N$2:$N$307,"Yes",Raw_Data!$C$2:$C$307,$B$3))/1000 -> 0 | K19: =IF(I19>0,RANK(I19,$I$6:$I$36)+COUNTIF($I$6:I19,I19)-1,"")
H20: Costa Verde Maquinarias S.A. | I20: =IF($B$3="All countries",SUMIFS(Raw_Data!$F$2:$F$307,Raw_Data!$J$2:$J$307,H20,Raw_Data!$O$2:$O$307,"Vehicles",Raw_Data!$N$2:$N$307,"Yes"),SUMIFS(Raw_Data!$F$2:$F$307,Raw_Data!$J$2:$J$307,H20,Raw_Data!$O$2:$O$307,"Vehicles",Raw_Data!$N$2:$N$307,"Yes",Raw_Data!$C$2:$C$307,$B$3)) -> 0 | J20: =IF($B$3="All countries",SUMIFS(Raw_Data!$P$2:$P$307,Raw_Data!$J$2:$J$307,H20,Raw_Data!$O$2:$O$307,"Vehicles",Raw_Data!$N$2:$N$307,"Yes"),SUMIFS(Raw_Data!$P$2:$P$307,Raw_Data!$J$2:$J$307,H20,Raw_Data!$O$2:$O$307,"Vehicles",Raw_Data!$N$2:$N$307,"Yes",Raw_Data!$C$2:$C$307,$B$3))/1000 -> 0 | K20: =IF(I20>0,RANK(I20,$I$6:$I$36)+COUNTIF($I$6:I20,I20)-1,"")
H21: Darien Construcciones S.A. | I21: =IF($B$3="All countries",SUMIFS(Raw_Data!$F$2:$F$307,Raw_Data!$J$2:$J$307,H21,Raw_Data!$O$2:$O$307,"Vehicles",Raw_Data!$N$2:$N$307,"Yes"),SUMIFS(Raw_Data!$F$2:$F$307,Raw_Data!$J$2:$J$307,H21,Raw_Data!$O$2:$O$307,"Vehicles",Raw_Data!$N$2:$N$307,"Yes",Raw_Data!$C$2:$C$307,$B$3)) -> 0 | J21: =IF($B$3="All countries",SUMIFS(Raw_Data!$P$2:$P$307,Raw_Data!$J$2:$J$307,H21,Raw_Data!$O$2:$O$307,"Vehicles",Raw_Data!$N$2:$N$307,"Yes"),SUMIFS(Raw_Data!$P$2:$P$307,Raw_Data!$J$2:$J$307,H21,Raw_Data!$O$2:$O$307,"Vehicles",Raw_Data!$N$2:$N$307,"Yes",Raw_Data!$C$2:$C$307,$B$3))/1000 -> 0 | K21: =IF(I21>0,RANK(I21,$I$6:$I$36)+COUNTIF($I$6:I21,I21)-1,"")
H22: Ecuamotors Cia. Ltda. | I22: =IF($B$3="All countries",SUMIFS(Raw_Data!$F$2:$F$307,Raw_Data!$J$2:$J$307,H22,Raw_Data!$O$2:$O$307,"Vehicles",Raw_Data!$N$2:$N$307,"Yes"),SUMIFS(Raw_Data!$F$2:$F$307,Raw_Data!$J$2:$J$307,H22,Raw_Data!$O$2:$O$307,"Vehicles",Raw_Data!$N$2:$N$307,"Yes",Raw_Data!$C$2:$C$307,$B$3)) -> 140 | J22: =IF($B$3="All countries",SUMIFS(Raw_Data!$P$2:$P$307,Raw_Data!$J$2:$J$307,H22,Raw_Data!$O$2:$O$307,"Vehicles",Raw_Data!$N$2:$N$307,"Yes"),SUMIFS(Raw_Data!$P$2:$P$307,Raw_Data!$J$2:$J$307,H22,Raw_Data!$O$2:$O$307,"Vehicles",Raw_Data!$N$2:$N$307,"Yes",Raw_Data!$C$2:$C$307,$B$3))/1000 -> 242.158 | K22: =IF(I22>0,RANK(I22,$I$6:$I$36)+COUNTIF($I$6:I22,I22)-1,"") -> 10
H23: Equinoccio Maquinaria S.A. | I23: =IF($B$3="All countries",SUMIFS(Raw_Data!$F$2:$F$307,Raw_Data!$J$2:$J$307,H23,Raw_Data!$O$2:$O$307,"Vehicles",Raw_Data!$N$2:$N$307,"Yes"),SUMIFS(Raw_Data!$F$2:$F$307,Raw_Data!$J$2:$J$307,H23,Raw_Data!$O$2:$O$307,"Vehicles",Raw_Data!$N$2:$N$307,"Yes",Raw_Data!$C$2:$C$307,$B$3)) -> 7 | J23: =IF($B$3="All countries",SUMIFS(Raw_Data!$P$2:$P$307,Raw_Data!$J$2:$J$307,H23,Raw_Data!$O$2:$O$307,"Vehicles",Raw_Data!$N$2:$N$307,"Yes"),SUMIFS(Raw_Data!$P$2:$P$307,Raw_Data!$J$2:$J$307,H23,Raw_Data!$O$2:$O$307,"Vehicles",Raw_Data!$N$2:$N$307,"Yes",Raw_Data!$C$2:$C$307,$B$3))/1000 -> 84.333 | K23: =IF(I23>0,RANK(I23,$I$6:$I$36)+COUNTIF($I$6:I23,I23)-1,"") -> 16
H24: Guayas Autos S.A. | I24: =IF($B$3="All countries",SUMIFS(Raw_Data!$F$2:$F$307,Raw_Data!$J$2:$J$307,H24,Raw_Data!$O$2:$O$307,"Vehicles",Raw_Data!$N$2:$N$307,"Yes"),SUMIFS(Raw_Data!$F$2:$F$307,Raw_Data!$J$2:$J$307,H24,Raw_Data!$O$2:$O$307,"Vehicles",Raw_Data!$N$2:$N$307,"Yes",Raw_Data!$C$2:$C$307,$B$3)) -> 267 | J24: =IF($B$3="All countries",SUMIFS(Raw_Data!$P$2:$P$307,Raw_Data!$J$2:$J$307,H24,Raw_Data!$O$2:$O$307,"Vehicles",Raw_Data!$N$2:$N$307,"Yes"),SUMIFS(Raw_Data!$P$2:$P$307,Raw_Data!$J$2:$J$307,H24,Raw_Data!$O$2:$O$307,"Vehicles",Raw_Data!$N$2:$N$307,"Yes",Raw_Data!$C$2:$C$307,$B$3))/1000 -> 1100.062 | K24: =IF(I24>0,RANK(I24,$I$6:$I$36)+COUNTIF($I$6:I24,I24)-1,"") -> 1
H25: Inca Automotriz S.A.C. | I25: =IF($B$3="All countries",SUMIFS(Raw_Data!$F$2:$F$307,Raw_Data!$J$2:$J$307,H25,Raw_Data!$O$2:$O$307,"Vehicles",Raw_Data!$N$2:$N$307,"Yes"),SUMIFS(Raw_Data!$F$2:$F$307,Raw_Data!$J$2:$J$307,H25,Raw_Data!$O$2:$O$307,"Vehicles",Raw_Data!$N$2:$N$307,"Yes",Raw_Data!$C$2:$C$307,$B$3)) -> 189 | J25: =IF($B$3="All countries",SUMIFS(Raw_Data!$P$2:$P$307,Raw_Data!$J$2:$J$307,H25,Raw_Data!$O$2:$O$307,"Vehicles",Raw_Data!$N$2:$N$307,"Yes"),SUMIFS(Raw_Data!$P$2:$P$307,Raw_Data!$J$2:$J$307,H25,Raw_Data!$O$2:$O$307,"Vehicles",Raw_Data!$N$2:$N$307,"Yes",Raw_Data!$C$2:$C$307,$B$3))/1000 -> 494.672 | K25: =IF(I25>0,RANK(I25,$I$6:$I$36)+COUNTIF($I$6:I25,I25)-1,"") -> 5
H26: Istmo Motors S.A. | I26: =IF($B$3="All countries",SUMIFS(Raw_Data!$F$2:$F$307,Raw_Data!$J$2:$J$307,H26,Raw_Data!$O$2:$O$307,"Vehicles",Raw_Data!$N$2:$N$307,"Yes"),SUMIFS(Raw_Data!$F$2:$F$307,Raw_Data!$J$2:$J$307,H26,Raw_Data!$O$2:$O$307,"Vehicles",Raw_Data!$N$2:$N$307,"Yes",Raw_Data!$C$2:$C$307,$B$3)) -> 161 | J26: =IF($B$3="All countries",SUMIFS(Raw_Data!$P$2:$P$307,Raw_Data!$J$2:$J$307,H26,Raw_Data!$O$2:$O$307,"Vehicles",Raw_Data!$N$2:$N$307,"Yes"),SUMIFS(Raw_Data!$P$2:$P$307,Raw_Data!$J$2:$J$307,H26,Raw_Data!$O$2:$O$307,"Vehicles",Raw_Data!$N$2:$N$307,"Yes",Raw_Data!$C$2:$C$307,$B$3))/1000 -> 408.196 | K26: =IF(I26>0,RANK(I26,$I$6:$I$36)+COUNTIF($I$6:I26,I26)-1,"") -> 7
H27: Lima Car Import S.A.C. | I27: =IF($B$3="All countries",SUMIFS(Raw_Data!$F$2:$F$307,Raw_Data!$J$2:$J$307,H27,Raw_Data!$O$2:$O$307,"Vehicles",Raw_Data!$N$2:$N$307,"Yes"),SUMIFS(Raw_Data!$F$2:$F$307,Raw_Data!$J$2:$J$307,H27,Raw_Data!$O$2:$O$307,"Vehicles",Raw_Data!$N$2:$N$307,"Yes",Raw_Data!$C$2:$C$307,$B$3)) -> 150 | J27: =IF($B$3="All countries",SUMIFS(Raw_Data!$P$2:$P$307,Raw_Data!$J$2:$J$307,H27,Raw_Data!$O$2:$O$307,"Vehicles",Raw_Data!$N$2:$N$307,"Yes"),SUMIFS(Raw_Data!$P$2:$P$307,Raw_Data!$J$2:$J$307,H27,Raw_Data!$O$2:$O$307,"Vehicles",Raw_Data!$N$2:$N$307,"Yes",Raw_Data!$C$2:$C$307,$B$3))/1000 -> 529.284 | K27: =IF(I27>0,RANK(I27,$I$6:$I$36)+COUNTIF($I$6:I27,I27)-1,"") -> 8
H28: Llanos Agro Equipos S.A.S. | I28: =IF($B$3="All countries",SUMIFS(Raw_Data!$F$2:$F$307,Raw_Data!$J$2:$J$307,H28,Raw_Data!$O$2:$O$307,"Vehicles",Raw_Data!$N$2:$N$307,"Yes"),SUMIFS(Raw_Data!$F$2:$F$307,Raw_Data!$J$2:$J$307,H28,Raw_Data!$O$2:$O$307,"Vehicles",Raw_Data!$N$2:$N$307,"Yes",Raw_Data!$C$2:$C$307,$B$3)) -> 0 | J28: =IF($B$3="All countries",SUMIFS(Raw_Data!$P$2:$P$307,Raw_Data!$J$2:$J$307,H28,Raw_Data!$O$2:$O$307,"Vehicles",Raw_Data!$N$2:$N$307,"Yes"),SUMIFS(Raw_Data!$P$2:$P$307,Raw_Data!$J$2:$J$307,H28,Raw_Data!$O$2:$O$307,"Vehicles",Raw_Data!$N$2:$N$307,"Yes",Raw_Data!$C$2:$C$307,$B$3))/1000 -> 0 | K28: =IF(I28>0,RANK(I28,$I$6:$I$36)+COUNTIF($I$6:I28,I28)-1,"")
H29: Maquinaria Andina S.A.S. | I29: =IF($B$3="All countries",SUMIFS(Raw_Data!$F$2:$F$307,Raw_Data!$J$2:$J$307,H29,Raw_Data!$O$2:$O$307,"Vehicles",Raw_Data!$N$2:$N$307,"Yes"),SUMIFS(Raw_Data!$F$2:$F$307,Raw_Data!$J$2:$J$307,H29,Raw_Data!$O$2:$O$307,"Vehicles",Raw_Data!$N$2:$N$307,"Yes",Raw_Data!$C$2:$C$307,$B$3)) -> 0 | J29: =IF($B$3="All countries",SUMIFS(Raw_Data!$P$2:$P$307,Raw_Data!$J$2:$J$307,H29,Raw_Data!$O$2:$O$307,"Vehicles",Raw_Data!$N$2:$N$307,"Yes"),SUMIFS(Raw_Data!$P$2:$P$307,Raw_Data!$J$2:$J$307,H29,Raw_Data!$O$2:$O$307,"Vehicles",Raw_Data!$N$2:$N$307,"Yes",Raw_Data!$C$2:$C$307,$B$3))/1000 -> 0 | K29: =IF(I29>0,RANK(I29,$I$6:$I$36)+COUNTIF($I$6:I29,I29)-1,"")
H30: Minera Equipos del Sur S.A.C. | I30: =IF($B$3="All countries",SUMIFS(Raw_Data!$F$2:$F$307,Raw_Data!$J$2:$J$307,H30,Raw_Data!$O$2:$O$307,"Vehicles",Raw_Data!$N$2:$N$307,"Yes"),SUMIFS(Raw_Data!$F$2:$F$307,Raw_Data!$J$2:$J$307,H30,Raw_Data!$O$2:$O$307,"Vehicles",Raw_Data!$N$2:$N$307,"Yes",Raw_Data!$C$2:$C$307,$B$3)) -> 0 | J30: =IF($B$3="All countries",SUMIFS(Raw_Data!$P$2:$P$307,Raw_Data!$J$2:$J$307,H30,Raw_Data!$O$2:$O$307,"Vehicles",Raw_Data!$N$2:$N$307,"Yes"),SUMIFS(Raw_Data!$P$2:$P$307,Raw_Data!$J$2:$J$307,H30,Raw_Data!$O$2:$O$307,"Vehicles",Raw_Data!$N$2:$N$307,"Yes",Raw_Data!$C$2:$C$307,$B$3))/1000 -> 0 | K30: =IF(I30>0,RANK(I30,$I$6:$I$36)+COUNTIF($I$6:I30,I30)-1,"")
H31: Pacific Bridge Equipment Inc. | I31: =IF($B$3="All countries",SUMIFS(Raw_Data!$F$2:$F$307,Raw_Data!$J$2:$J$307,H31,Raw_Data!$O$2:$O$307,"Vehicles",Raw_Data!$N$2:$N$307,"Yes"),SUMIFS(Raw_Data!$F$2:$F$307,Raw_Data!$J$2:$J$307,H31,Raw_Data!$O$2:$O$307,"Vehicles",Raw_Data!$N$2:$N$307,"Yes",Raw_Data!$C$2:$C$307,$B$3)) -> 0 | J31: =IF($B$3="All countries",SUMIFS(Raw_Data!$P$2:$P$307,Raw_Data!$J$2:$J$307,H31,Raw_Data!$O$2:$O$307,"Vehicles",Raw_Data!$N$2:$N$307,"Yes"),SUMIFS(Raw_Data!$P$2:$P$307,Raw_Data!$J$2:$J$307,H31,Raw_Data!$O$2:$O$307,"Vehicles",Raw_Data!$N$2:$N$307,"Yes",Raw_Data!$C$2:$C$307,$B$3))/1000 -> 0 | K31: =IF(I31>0,RANK(I31,$I$6:$I$36)+COUNTIF($I$6:I31,I31)-1,"")
... H36: Transcargo Pesados S.A.S. | I36: =IF($B$3="All countries",SUMIFS(Raw_Data!$F$2:$F$307,Raw_Data!$J$2:$J$307,H36,Raw_Data!$O$2:$O$307,"Vehicles",Raw_Data!$N$2:$N$307,"Yes"),SUMIFS(Raw_Data!$F$2:$F$307,Raw_Data!$J$2:$J$307,H36,Raw_Data!$O$2:$O$307,"Vehicles",Raw_Data!$N$2:$N$307,"Yes",Raw_Data!$C$2:$C$307,$B$3)) -> 0 | J36: =IF($B$3="All countries",SUMIFS(Raw_Data!$P$2:$P$307,Raw_Data!$J$2:$J$307,H36,Raw_Data!$O$2:$O$307,"Vehicles",Raw_Data!$N$2:$N$307,"Yes"),SUMIFS(Raw_Data!$P$2:$P$307,Raw_Data!$J$2:$J$307,H36,Raw_Data!$O$2:$O$307,"Vehicles",Raw_Data!$N$2:$N$307,"Yes",Raw_Data!$C$2:$C$307,$B$3))/1000 -> 0 | K36: =IF(I36>0,RANK(I36,$I$6:$I$36)+COUNTIF($I$6:I36,I36)-1,"")

Sheet Ranking_HH
A1: Top 10 importers — High & Heavy (> 15 t/unit)
A2: US East Coast origin only. Fictional data.
A3: Country: | B3: All countries
H4: Calculation table (all importers)
A5: Rank | B5: Importer | C5: Units | D5: Weight (t) | E5: Market share | H5: Importer (all) | I5: Units | J5: Weight (t) | K5: Rank
A6: 1 | B6: =IFERROR(INDEX($H$6:$H$36,MATCH(A6,$K$6:$K$36,0)),"") -> Equinoccio Maquinaria S.A. | C6: =IFERROR(INDEX($I$6:$I$36,MATCH(A6,$K$6:$K$36,0)),"") -> 18 | D6: =IFERROR(INDEX($J$6:$J$36,MATCH(A6,$K$6:$K$36,0)),"") -> 614.316 | E6: =IF(C6="","",C6/$C$18) -> 0.144 | H6: Altiplano Trucks S.A.C. | I6: =IF($B$3="All countries",SUMIFS(Raw_Data!$F$2:$F$307,Raw_Data!$J$2:$J$307,H6,Raw_Data!$O$2:$O$307,"H&H",Raw_Data!$N$2:$N$307,"Yes"),SUMIFS(Raw_Data!$F$2:$F$307,Raw_Data!$J$2:$J$307,H6,Raw_Data!$O$2:$O$307,"H&H",Raw_Data!$N$2:$N$307,"Yes",Raw_Data!$C$2:$C$307,$B$3)) -> 10 | J6: =IF($B$3="All countries",SUMIFS(Raw_Data!$P$2:$P$307,Raw_Data!$J$2:$J$307,H6,Raw_Data!$O$2:$O$307,"H&H",Raw_Data!$N$2:$N$307,"Yes"),SUMIFS(Raw_Data!$P$2:$P$307,Raw_Data!$J$2:$J$307,H6,Raw_Data!$O$2:$O$307,"H&H",Raw_Data!$N$2:$N$307,"Yes",Raw_Data!$C$2:$C$307,$B$3))/1000 -> 550.482 | K6: =IF(I6>0,RANK(I6,$I$6:$I$36)+COUNTIF($I$6:I6,I6)-1,"") -> 3
A7: 2 | B7: =IFERROR(INDEX($H$6:$H$36,MATCH(A7,$K$6:$K$36,0)),"") -> Antillas Cargo Logistics S.R.L. | C7: =IFERROR(INDEX($I$6:$I$36,MATCH(A7,$K$6:$K$36,0)),"") -> 16 | D7: =IFERROR(INDEX($J$6:$J$36,MATCH(A7,$K$6:$K$36,0)),"") -> 660.571 | E7: =IF(C7="","",C7/$C$18) -> 0.128 | H7: Andes Motor Group S.A. | I7: =IF($B$3="All countries",SUMIFS(Raw_Data!$F$2:$F$307,Raw_Data!$J$2:$J$307,H7,Raw_Data!$O$2:$O$307,"H&H",Raw_Data!$N$2:$N$307,"Yes"),SUMIFS(Raw_Data!$F$2:$F$307,Raw_Data!$J$2:$J$307,H7,Raw_Data!$O$2:$O$307,"H&H",Raw_Data!$N$2:$N$307,"Yes",Raw_Data!$C$2:$C$307,$B$3)) -> 0 | J7: =IF($B$3="All countries",SUMIFS(Raw_Data!$P$2:$P$307,Raw_Data!$J$2:$J$307,H7,Raw_Data!$O$2:$O$307,"H&H",Raw_Data!$N$2:$N$307,"Yes"),SUMIFS(Raw_Data!$P$2:$P$307,Raw_Data!$J$2:$J$307,H7,Raw_Data!$O$2:$O$307,"H&H",Raw_Data!$N$2:$N$307,"Yes",Raw_Data!$C$2:$C$307,$B$3))/1000 -> 0 | K7: =IF(I7>0,RANK(I7,$I$6:$I$36)+COUNTIF($I$6:I7,I7)-1,"")
A8: 3 | B8: =IFERROR(INDEX($H$6:$H$36,MATCH(A8,$K$6:$K$36,0)),"") -> Altiplano Trucks S.A.C. | C8: =IFERROR(INDEX($I$6:$I$36,MATCH(A8,$K$6:$K$36,0)),"") -> 10 | D8: =IFERROR(INDEX($J$6:$J$36,MATCH(A8,$K$6:$K$36,0)),"") -> 550.482 | E8: =IF(C8="","",C8/$C$18) -> 0.08 | H8: Antillas Cargo Logistics S.R.L. | I8: =IF($B$3="All countries",SUMIFS(Raw_Data!$F$2:$F$307,Raw_Data!$J$2:$J$307,H8,Raw_Data!$O$2:$O$307,"H&H",Raw_Data!$N$2:$N$307,"Yes"),SUMIFS(Raw_Data!$F$2:$F$307,Raw_Data!$J$2:$J$307,H8,Raw_Data!$O$2:$O$307,"H&H",Raw_Data!$N$2:$N$307,"Yes",Raw_Data!$C$2:$C$307,$B$3)) -> 16 | J8: =IF($B$3="All countries",SUMIFS(Raw_Data!$P$2:$P$307,Raw_Data!$J$2:$J$307,H8,Raw_Data!$O$2:$O$307,"H&H",Raw_Data!$N$2:$N$307,"Yes"),SUMIFS(Raw_Data!$P$2:$P$307,Raw_Data!$J$2:$J$307,H8,Raw_Data!$O$2:$O$307,"H&H",Raw_Data!$N$2:$N$307,"Yes",Raw_Data!$C$2:$C$307,$B$3))/1000 -> 660.571 | K8: =IF(I8>0,RANK(I8,$I$6:$I$36)+COUNTIF($I$6:I8,I8)-1,"") -> 2
A9: 4 | B9: =IFERROR(INDEX($H$6:$H$36,MATCH(A9,$K$6:$K$36,0)),"") -> Chiriqui Agro Machinery S.A. | C9: =IFERROR(INDEX($I$6:$I$36,MATCH(A9,$K$6:$K$36,0)),"") -> 10 | D9: =IFERROR(INDEX($J$6:$J$36,MATCH(A9,$K$6:$K$36,0)),"") -> 398.389 | E9: =IF(C9="","",C9/$C$18) -> 0.08 | H9: Atacama Equipos Mineros S.A. | I9: =IF($B$3="All countries",SUMIFS(Raw_Data!$F$2:$F$307,Raw_Data!$J$2:$J$307,H9,Raw_Data!$O$2:$O$307,"H&H",Raw_Data!$N$2:$N$307,"Yes"),SUMIFS(Raw_Data!$F$2:$F$307,Raw_Data!$J$2:$J$307,H9,Raw_Data!$O$2:$O$307,"H&H",Raw_Data!$N$2:$N$307,"Yes",Raw_Data!$C$2:$C$307,$B$3)) -> 8 | J9: =IF($B$3="All countries",SUMIFS(Raw_Data!$P$2:$P$307,Raw_Data!$J$2:$J$307,H9,Raw_Data!$O$2:$O$307,"H&H",Raw_Data!$N$2:$N$307,"Yes"),SUMIFS(Raw_Data!$P$2:$P$307,Raw_Data!$J$2:$J$307,H9,Raw_Data!$O$2:$O$307,"H&H",Raw_Data!$N$2:$N$307,"Yes",Raw_Data!$C$2:$C$307,$B$3))/1000 -> 292.203 | K9: =IF(I9>0,RANK(I9,$I$6:$I$36)+COUNTIF($I$6:I9,I9)-1,"") -> 6
A10: 5 | B10: =IFERROR(INDEX($H$6:$H$36,MATCH(A10,$K$6:$K$36,0)),"") -> Colon Free Zone Traders S.A. | C10: =IFERROR(INDEX($I$6:$I$36,MATCH(A10,$K$6:$K$36,0)),"") -> 9 | D10: =IFERROR(INDEX($J$6:$J$36,MATCH(A10,$K$6:$K$36,0)),"") -> 245.89 | E10: =IF(C10="","",C10/$C$18) -> 0.072 | H10: Austral Truck Center SpA | I10: =IF($B$3="All countries",SUMIFS(Raw_Data!$F$2:$F$307,Raw_Data!$J$2:$J$307,H10,Raw_Data!$O$2:$O$307,"H&H",Raw_Data!$N$2:$N$307,"Yes"),SUMIFS(Raw_Data!$F$2:$F$307,Raw_Data!$J$2:$J$307,H10,Raw_Data!$O$2:$O$307,"H&H",Raw_Data!$N$2:$N$307,"Yes",Raw_Data!$C$2:$C$307,$B$3)) -> 8 | J10: =IF($B$3="All countries",SUMIFS(Raw_Data!$P$2:$P$307,Raw_Data!$J$2:$J$307,H10,Raw_Data!$O$2:$O$307,"H&H",Raw_Data!$N$2:$N$307,"Yes"),SUMIFS(Raw_Data!$P$2:$P$307,Raw_Data!$J$2:$J$307,H10,Raw_Data!$O$2:$O$307,"H&H",Raw_Data!$N$2:$N$307,"Yes",Raw_Data!$C$2:$C$307,$B$3))/1000 -> 259.274 | K10: =IF(I10>0,RANK(I10,$I$6:$I$36)+COUNTIF($I$6:I10,I10)-1,"") -> 7
A11: 6 | B11: =IFERROR(INDEX($H$6:$H$36,MATCH(A11,$K$6:$K$36,0)),"") -> Atacama Equipos Mineros S.A. | C11: =IFERROR(INDEX($I$6:$I$36,MATCH(A11,$K$6:$K$36,0)),"") -> 8 | D11: =IFERROR(INDEX($J$6:$J$36,MATCH(A11,$K$6:$K$36,0)),"") -> 292.203 | E11: =IF(C11="","",C11/$C$18) -> 0.064 | H11: Autonorte Distribuciones S.A.S. | I11: =IF($B$3="All countries",SUMIFS(Raw_Data!$F$2:$F$307,Raw_Data!$J$2:$J$307,H11,Raw_Data!$O$2:$O$307,"H&H",Raw_Data!$N$2:$N$307,"Yes"),SUMIFS(Raw_Data!$F$2:$F$307,Raw_Data!$J$2:$J$307,H11,Raw_Data!$O$2:$O$307,"H&H",Raw_Data!$N$2:$N$307,"Yes",Raw_Data!$C$2:$C$307,$B$3)) -> 0 | J11: =IF($B$3="All countries",SUMIFS(Raw_Data!$P$2:$P$307,Raw_Data!$J$2:$J$307,H11,Raw_Data!$O$2:$O$307,"H&H",Raw_Data!$N$2:$N$307,"Yes"),SUMIFS(Raw_Data!$P$2:$P$307,Raw_Data!$J$2:$J$307,H11,Raw_Data!$O$2:$O$307,"H&H",Raw_Data!$N$2:$N$307,"Yes",Raw_Data!$C$2:$C$307,$B$3))/1000 -> 0 | K11: =IF(I11>0,RANK(I11,$I$6:$I$36)+COUNTIF($I$6:I11,I11)-1,"")
A12: 7 | B12: =IFERROR(INDEX($H$6:$H$36,MATCH(A12,$K$6:$K$36,0)),"") -> Austral Truck Center SpA | C12: =IFERROR(INDEX($I$6:$I$36,MATCH(A12,$K$6:$K$36,0)),"") -> 8 | D12: =IFERROR(INDEX($J$6:$J$36,MATCH(A12,$K$6:$K$36,0)),"") -> 259.274 | E12: =IF(C12="","",C12/$C$18) -> 0.064 | H12: Bogota Car Import S.A.S. | I12: =IF($B$3="All countries",SUMIFS(Raw_Data!$F$2:$F$307,Raw_Data!$J$2:$J$307,H12,Raw_Data!$O$2:$O$307,"H&H",Raw_Data!$N$2:$N$307,"Yes"),SUMIFS(Raw_Data!$F$2:$F$307,Raw_Data!$J$2:$J$307,H12,Raw_Data!$O$2:$O$307,"H&H",Raw_Data!$N$2:$N$307,"Yes",Raw_Data!$C$2:$C$307,$B$3)) -> 0 | J12: =IF($B$3="All countries",SUMIFS(Raw_Data!$P$2:$P$307,Raw_Data!$J$2:$J$307,H12,Raw_Data!$O$2:$O$307,"H&H",Raw_Data!$N$2:$N$307,"Yes"),SUMIFS(Raw_Data!$P$2:$P$307,Raw_Data!$J$2:$J$307,H12,Raw_Data!$O$2:$O$307,"H&H",Raw_Data!$N$2:$N$307,"Yes",Raw_Data!$C$2:$C$307,$B$3))/1000 -> 0 | K12: =IF(I12>0,RANK(I12,$I$6:$I$36)+COUNTIF($I$6:I12,I12)-1,"")
A13: 8 | B13: =IFERROR(INDEX($H$6:$H$36,MATCH(A13,$K$6:$K$36,0)),"") -> Darien Construcciones S.A. | C13: =IFERROR(INDEX($I$6:$I$36,MATCH(A13,$K$6:$K$36,0)),"") -> 8 | D13: =IFERROR(INDEX($J$6:$J$36,MATCH(A13,$K$6:$K$36,0)),"") -> 175.194 | E13: =IF(C13="","",C13/$C$18) -> 0.064 | H13: Canal Autos S.A. | I13: =IF($B$3="All countries",SUMIFS(Raw_Data!$F$2:$F$307,Raw_Data!$J$2:$J$307,H13,Raw_Data!$O$2:$O$307,"H&H",Raw_Data!$N$2:$N$307,"Yes"),SUMIFS(Raw_Data!$F$2:$F$307,Raw_Data!$J$2:$J$307,H13,Raw_Data!$O$2:$O$307,"H&H",Raw_Data!$N$2:$N$307,"Yes",Raw_Data!$C$2:$C$307,$B$3)) -> 0 | J13: =IF($B$3="All countries",SUMIFS(Raw_Data!$P$2:$P$307,Raw_Data!$J$2:$J$307,H13,Raw_Data!$O$2:$O$307,"H&H",Raw_Data!$N$2:$N$307,"Yes"),SUMIFS(Raw_Data!$P$2:$P$307,Raw_Data!$J$2:$J$307,H13,Raw_Data!$O$2:$O$307,"H&H",Raw_Data!$N$2:$N$307,"Yes",Raw_Data!$C$2:$C$307,$B$3))/1000 -> 0 | K13: =IF(I13>0,RANK(I13,$I$6:$I$36)+COUNTIF($I$6:I13,I13)-1,"")
A14: 9 | B14: =IFERROR(INDEX($H$6:$H$36,MATCH(A14,$K$6:$K$36,0)),"") -> Transcargo Pesados S.A.S. | C14: =IFERROR(INDEX($I$6:$I$36,MATCH(A14,$K$6:$K$36,0)),"") -> 8 | D14: =IFERROR(INDEX($J$6:$J$36,MATCH(A14,$K$6:$K$36,0)),"") -> 370.327 | E14: =IF(C14="","",C14/$C$18) -> 0.064 | H14: Caribbean Freight Express S.R.L. | I14: =IF($B$3="All countries",SUMIFS(Raw_Data!$F$2:$F$307,Raw_Data!$J$2:$J$307,H14,Raw_Data!$O$2:$O$307,"H&H",Raw_Data!$N$2:$N$307,"Yes"),SUMIFS(Raw_Data!$F$2:$F$307,Raw_Data!$J$2:$J$307,H14,Raw_Data!$O$2:$O$307,"H&H",Raw_Data!$N$2:$N$307,"Yes",Raw_Data!$C$2:$C$307,$B$3)) -> 6 | J14: =IF($B$3="All countries",SUMIFS(Raw_Data!$P$2:$P$307,Raw_Data!$J$2:$J$307,H14,Raw_Data!$O$2:$O$307,"H&H",Raw_Data!$N$2:$N$307,"Yes"),SUMIFS(Raw_Data!$P$2:$P$307,Raw_Data!$J$2:$J$307,H14,Raw_Data!$O$2:$O$307,"H&H",Raw_Data!$N$2:$N$307,"Yes",Raw_Data!$C$2:$C$307,$B$3))/1000 -> 309.217 | K14: =IF(I14>0,RANK(I14,$I$6:$I$36)+COUNTIF($I$6:I14,I14)-1,"") -> 10
A15: 10 | B15: =IFERROR(INDEX($H$6:$H$36,MATCH(A15,$K$6:$K$36,0)),"") -> Caribbean Freight Express S.R.L. | C15: =IFERROR(INDEX($I$6:$I$36,MATCH(A15,$K$6:$K$36,0)),"") -> 6 | D15: =IFERROR(INDEX($J$6:$J$36,MATCH(A15,$K$6:$K$36,0)),"") -> 309.217 | E15: =IF(C15="","",C15/$C$18) -> 0.048 | H15: Caribe Motores S.A.S. | I15: =IF($B$3="All countries",SUMIFS(Raw_Data!$F$2:$F$307,Raw_Data!$J$2:$J$307,H15,Raw_Data!$O$2:$O$307,"H&H",Raw_Data!$N$2:$N$307,"Yes"),SUMIFS(Raw_Data!$F$2:$F$307,Raw_Data!$J$2:$J$307,H15,Raw_Data!$O$2:$O$307,"H&H",Raw_Data!$N$2:$N$307,"Yes",Raw_Data!$C$2:$C$307,$B$3)) -> 0 | J15: =IF($B$3="All countries",SUMIFS(Raw_Data!$P$2:$P$307,Raw_Data!$J$2:$J$307,H15,Raw_Data!$O$2:$O$307,"H&H",Raw_Data!$N$2:$N$307,"Yes"),SUMIFS(Raw_Data!$P$2:$P$307,Raw_Data!$J$2:$J$307,H15,Raw_Data!$O$2:$O$307,"H&H",Raw_Data!$N$2:$N$307,"Yes",Raw_Data!$C$2:$C$307,$B$3))/1000 -> 0 | K15: =IF(I15>0,RANK(I15,$I$6:$I$36)+COUNTIF($I$6:I15,I15)-1,"")
B16: Top 10 total | C16: =SUM(C6:C15) -> 101 | E16: =IF($C$18>0,C16/$C$18,0) -> 0.808 | H16: Chiriqui Agro Machinery S.A. | I16: =IF($B$3="All countries",SUMIFS(Raw_Data!$F$2:$F$307,Raw_Data!$J$2:$J$307,H16,Raw_Data!$O$2:$O$307,"H&H",Raw_Data!$N$2:$N$307,"Yes"),SUMIFS(Raw_Data!$F$2:$F$307,Raw_Data!$J$2:$J$307,H16,Raw_Data!$O$2:$O$307,"H&H",Raw_Data!$N$2:$N$307,"Yes",Raw_Data!$C$2:$C$307,$B$3)) -> 10 | J16: =IF($B$3="All countries",SUMIFS(Raw_Data!$P$2:$P$307,Raw_Data!$J$2:$J$307,H16,Raw_Data!$O$2:$O$307,"H&H",Raw_Data!$N$2:$N$307,"Yes"),SUMIFS(Raw_Data!$P$2:$P$307,Raw_Data!$J$2:$J$307,H16,Raw_Data!$O$2:$O$307,"H&H",Raw_Data!$N$2:$N$307,"Yes",Raw_Data!$C$2:$C$307,$B$3))/1000 -> 398.389 | K16: =IF(I16>0,RANK(I16,$I$6:$I$36)+COUNTIF($I$6:I16,I16)-1,"") -> 4
B17: Rest of importers | C17: =C18-C16 -> 24 | E17: =IF($C$18>0,C17/$C$18,0) -> 0.192 | H17: Cibao Equipos S.R.L. | I17: =IF($B$3="All countries",SUMIFS(Raw_Data!$F$2:$F$307,Raw_Data!$J$2:$J$307,H17,Raw_Data!$O$2:$O$307,"H&H",Raw_Data!$N$2:$N$307,"Yes"),SUMIFS(Raw_Data!$F$2:$F$307,Raw_Data!$J$2:$J$307,H17,Raw_Data!$O$2:$O$307,"H&H",Raw_Data!$N$2:$N$307,"Yes",Raw_Data!$C$2:$C$307,$B$3)) -> 6 | J17: =IF($B$3="All countries",SUMIFS(Raw_Data!$P$2:$P$307,Raw_Data!$J$2:$J$307,H17,Raw_Data!$O$2:$O$307,"H&H",Raw_Data!$N$2:$N$307,"Yes"),SUMIFS(Raw_Data!$P$2:$P$307,Raw_Data!$J$2:$J$307,H17,Raw_Data!$O$2:$O$307,"H&H",Raw_Data!$N$2:$N$307,"Yes",Raw_Data!$C$2:$C$307,$B$3))/1000 -> 308.224 | K17: =IF(I17>0,RANK(I17,$I$6:$I$36)+COUNTIF($I$6:I17,I17)-1,"") -> 11
B18: Total market | C18: =SUM(I6:I36) -> 125 | E18: =IF($C$18>0,1,0) -> 1 | H18: Colon Free Zone Traders S.A. | I18: =IF($B$3="All countries",SUMIFS(Raw_Data!$F$2:$F$307,Raw_Data!$J$2:$J$307,H18,Raw_Data!$O$2:$O$307,"H&H",Raw_Data!$N$2:$N$307,"Yes"),SUMIFS(Raw_Data!$F$2:$F$307,Raw_Data!$J$2:$J$307,H18,Raw_Data!$O$2:$O$307,"H&H",Raw_Data!$N$2:$N$307,"Yes",Raw_Data!$C$2:$C$307,$B$3)) -> 9 | J18: =IF($B$3="All countries",SUMIFS(Raw_Data!$P$2:$P$307,Raw_Data!$J$2:$J$307,H18,Raw_Data!$O$2:$O$307,"H&H",Raw_Data!$N$2:$N$307,"Yes"),SUMIFS(Raw_Data!$P$2:$P$307,Raw_Data!$J$2:$J$307,H18,Raw_Data!$O$2:$O$307,"H&H",Raw_Data!$N$2:$N$307,"Yes",Raw_Data!$C$2:$C$307,$B$3))/1000 -> 245.89 | K18: =IF(I18>0,RANK(I18,$I$6:$I$36)+COUNTIF($I$6:I18,I18)-1,"") -> 5
B19: Number of active importers | C19: =COUNTIF(I6:I36,">0") -> 17 | H19: Cordillera Maquinarias SpA | I19: =IF($B$3="All countries",SUMIFS(Raw_Data!$F$2:$F$307,Raw_Data!$J$2:$J$307,H19,Raw_Data!$O$2:$O$307,"H&H",Raw_Data!$N$2:$N$307,"Yes"),SUMIFS(Raw_Data!$F$2:$F$307,Raw_Data!$J$2:$J$307,H19,Raw_Data!$O$2:$O$307,"H&H",Raw_Data!$N$2:$N$307,"Yes",Raw_Data!$C$2:$C$307,$B$3)) -> 1 | J19: =IF($B$3="All countries",SUMIFS(Raw_Data!$P$2:$P$307,Raw_Data!$J$2:$J$307,H19,Raw_Data!$O$2:$O$307,"H&H",Raw_Data!$N$2:$N$307,"Yes"),SUMIFS(Raw_Data!$P$2:$P$307,Raw_Data!$J$2:$J$307,H19,Raw_Data!$O$2:$O$307,"H&H",Raw_Data!$N$2:$N$307,"Yes",Raw_Data!$C$2:$C$307,$B$3))/1000 -> 19.307 | K19: =IF(I19>0,RANK(I19,$I$6:$I$36)+COUNTIF($I$6:I19,I19)-1,"") -> 17
H20: Costa Verde Maquinarias S.A. | I20: =IF($B$3="All countries",SUMIFS(Raw_Data!$F$2:$F$307,Raw_Data!$J$2:$J$307,H20,Raw_Data!$O$2:$O$307,"H&H",Raw_Data!$N$2:$N$307,"Yes"),SUMIFS(Raw_Data!$F$2:$F$307,Raw_Data!$J$2:$J$307,H20,Raw_Data!$O$2:$O$307,"H&H",Raw_Data!$N$2:$N$307,"Yes",Raw_Data!$C$2:$C$307,$B$3)) -> 0 | J20: =IF($B$3="All countries",SUMIFS(Raw_Data!$P$2:$P$307,Raw_Data!$J$2:$J$307,H20,Raw_Data!$O$2:$O$307,"H&H",Raw_Data!$N$2:$N$307,"Yes"),SUMIFS(Raw_Data!$P$2:$P$307,Raw_Data!$J$2:$J$307,H20,Raw_Data!$O$2:$O$307,"H&H",Raw_Data!$N$2:$N$307,"Yes",Raw_Data!$C$2:$C$307,$B$3))/1000 -> 0 | K20: =IF(I20>0,RANK(I20,$I$6:$I$36)+COUNTIF($I$6:I20,I20)-1,"")
H21: Darien Construcciones S.A. | I21: =IF($B$3="All countries",SUMIFS(Raw_Data!$F$2:$F$307,Raw_Data!$J$2:$J$307,H21,Raw_Data!$O$2:$O$307,"H&H",Raw_Data!$N$2:$N$307,"Yes"),SUMIFS(Raw_Data!$F$2:$F$307,Raw_Data!$J$2:$J$307,H21,Raw_Data!$O$2:$O$307,"H&H",Raw_Data!$N$2:$N$307,"Yes",Raw_Data!$C$2:$C$307,$B$3)) -> 8 | J21: =IF($B$3="All countries",SUMIFS(Raw_Data!$P$2:$P$307,Raw_Data!$J$2:$J$307,H21,Raw_Data!$O$2:$O$307,"H&H",Raw_Data!$N$2:$N$307,"Yes"),SUMIFS(Raw_Data!$P$2:$P$307,Raw_Data!$J$2:$J$307,H21,Raw_Data!$O$2:$O$307,"H&H",Raw_Data!$N$2:$N$307,"Yes",Raw_Data!$C$2:$C$307,$B$3))/1000 -> 175.194 | K21: =IF(I21>0,RANK(I21,$I$6:$I$36)+COUNTIF($I$6:I21,I21)-1,"") -> 8
H22: Ecuamotors Cia. Ltda. | I22: =IF($B$3="All countries",SUMIFS(Raw_Data!$F$2:$F$307,Raw_Data!$J$2:$J$307,H22,Raw_Data!$O$2:$O$307,"H&H",Raw_Data!$N$2:$N$307,"Yes"),SUMIFS(Raw_Data!$F$2:$F$307,Raw_Data!$J$2:$J$307,H22,Raw_Data!$O$2:$O$307,"H&H",Raw_Data!$N$2:$N$307,"Yes",Raw_Data!$C$2:$C$307,$B$3)) -> 0 | J22: =IF($B$3="All countries",SUMIFS(Raw_Data!$P$2:$P$307,Raw_Data!$J$2:$J$307,H22,Raw_Data!$O$2:$O$307,"H&H",Raw_Data!$N$2:$N$307,"Yes"),SUMIFS(Raw_Data!$P$2:$P$307,Raw_Data!$J$2:$J$307,H22,Raw_Data!$O$2:$O$307,"H&H",Raw_Data!$N$2:$N$307,"Yes",Raw_Data!$C$2:$C$307,$B$3))/1000 -> 0 | K22: =IF(I22>0,RANK(I22,$I$6:$I$36)+COUNTIF($I$6:I22,I22)-1,"")
H23: Equinoccio Maquinaria S.A. | I23: =IF($B$3="All countries",SUMIFS(Raw_Data!$F$2:$F$307,Raw_Data!$J$2:$J$307,H23,Raw_Data!$O$2:$O$307,"H&H",Raw_Data!$N$2:$N$307,"Yes"),SUMIFS(Raw_Data!$F$2:$F$307,Raw_Data!$J$2:$J$307,H23,Raw_Data!$O$2:$O$307,"H&H",Raw_Data!$N$2:$N$307,"Yes",Raw_Data!$C$2:$C$307,$B$3)) -> 18 | J23: =IF($B$3="All countries",SUMIFS(Raw_Data!$P$2:$P$307,Raw_Data!$J$2:$J$307,H23,Raw_Data!$O$2:$O$307,"H&H",Raw_Data!$N$2:$N$307,"Yes"),SUMIFS(Raw_Data!$P$2:$P$307,Raw_Data!$J$2:$J$307,H23,Raw_Data!$O$2:$O$307,"H&H",Raw_Data!$N$2:$N$307,"Yes",Raw_Data!$C$2:$C$307,$B$3))/1000 -> 614.316 | K23: =IF(I23>0,RANK(I23,$I$6:$I$36)+COUNTIF($I$6:I23,I23)-1,"") -> 1
H24: Guayas Autos S.A. | I24: =IF($B$3="All countries",SUMIFS(Raw_Data!$F$2:$F$307,Raw_Data!$J$2:$J$307,H24,Raw_Data!$O$2:$O$307,"H&H",Raw_Data!$N$2:$N$307,"Yes"),SUMIFS(Raw_Data!$F$2:$F$307,Raw_Data!$J$2:$J$307,H24,Raw_Data!$O$2:$O$307,"H&H",Raw_Data!$N$2:$N$307,"Yes",Raw_Data!$C$2:$C$307,$B$3)) -> 0 | J24: =IF($B$3="All countries",SUMIFS(Raw_Data!$P$2:$P$307,Raw_Data!$J$2:$J$307,H24,Raw_Data!$O$2:$O$307,"H&H",Raw_Data!$N$2:$N$307,"Yes"),SUMIFS(Raw_Data!$P$2:$P$307,Raw_Data!$J$2:$J$307,H24,Raw_Data!$O$2:$O$307,"H&H",Raw_Data!$N$2:$N$307,"Yes",Raw_Data!$C$2:$C$307,$B$3))/1000 -> 0 | K24: =IF(I24>0,RANK(I24,$I$6:$I$36)+COUNTIF($I$6:I24,I24)-1,"")
H25: Inca Automotriz S.A.C. | I25: =IF($B$3="All countries",SUMIFS(Raw_Data!$F$2:$F$307,Raw_Data!$J$2:$J$307,H25,Raw_Data!$O$2:$O$307,"H&H",Raw_Data!$N$2:$N$307,"Yes"),SUMIFS(Raw_Data!$F$2:$F$307,Raw_Data!$J$2:$J$307,H25,Raw_Data!$O$2:$O$307,"H&H",Raw_Data!$N$2:$N$307,"Yes",Raw_Data!$C$2:$C$307,$B$3)) -> 0 | J25: =IF($B$3="All countries",SUMIFS(Raw_Data!$P$2:$P$307,Raw_Data!$J$2:$J$307,H25,Raw_Data!$O$2:$O$307,"H&H",Raw_Data!$N$2:$N$307,"Yes"),SUMIFS(Raw_Data!$P$2:$P$307,Raw_Data!$J$2:$J$307,H25,Raw_Data!$O$2:$O$307,"H&H",Raw_Data!$N$2:$N$307,"Yes",Raw_Data!$C$2:$C$307,$B$3))/1000 -> 0 | K25: =IF(I25>0,RANK(I25,$I$6:$I$36)+COUNTIF($I$6:I25,I25)-1,"")
H26: Istmo Motors S.A. | I26: =IF($B$3="All countries",SUMIFS(Raw_Data!$F$2:$F$307,Raw_Data!$J$2:$J$307,H26,Raw_Data!$O$2:$O$307,"H&H",Raw_Data!$N$2:$N$307,"Yes"),SUMIFS(Raw_Data!$F$2:$F$307,Raw_Data!$J$2:$J$307,H26,Raw_Data!$O$2:$O$307,"H&H",Raw_Data!$N$2:$N$307,"Yes",Raw_Data!$C$2:$C$307,$B$3)) -> 0 | J26: =IF($B$3="All countries",SUMIFS(Raw_Data!$P$2:$P$307,Raw_Data!$J$2:$J$307,H26,Raw_Data!$O$2:$O$307,"H&H",Raw_Data!$N$2:$N$307,"Yes"),SUMIFS(Raw_Data!$P$2:$P$307,Raw_Data!$J$2:$J$307,H26,Raw_Data!$O$2:$O$307,"H&H",Raw_Data!$N$2:$N$307,"Yes",Raw_Data!$C$2:$C$307,$B$3))/1000 -> 0 | K26: =IF(I26>0,RANK(I26,$I$6:$I$36)+COUNTIF($I$6:I26,I26)-1,"")
H27: Lima Car Import S.A.C. | I27: =IF($B$3="All countries",SUMIFS(Raw_Data!$F$2:$F$307,Raw_Data!$J$2:$J$307,H27,Raw_Data!$O$2:$O$307,"H&H",Raw_Data!$N$2:$N$307,"Yes"),SUMIFS(Raw_Data!$F$2:$F$307,Raw_Data!$J$2:$J$307,H27,Raw_Data!$O$2:$O$307,"H&H",Raw_Data!$N$2:$N$307,"Yes",Raw_Data!$C$2:$C$307,$B$3)) -> 0 | J27: =IF($B$3="All countries",SUMIFS(Raw_Data!$P$2:$P$307,Raw_Data!$J$2:$J$307,H27,Raw_Data!$O$2:$O$307,"H&H",Raw_Data!$N$2:$N$307,"Yes"),SUMIFS(Raw_Data!$P$2:$P$307,Raw_Data!$J$2:$J$307,H27,Raw_Data!$O$2:$O$307,"H&H",Raw_Data!$N$2:$N$307,"Yes",Raw_Data!$C$2:$C$307,$B$3))/1000 -> 0 | K27: =IF(I27>0,RANK(I27,$I$6:$I$36)+COUNTIF($I$6:I27,I27)-1,"")
H28: Llanos Agro Equipos S.A.S. | I28: =IF($B$3="All countries",SUMIFS(Raw_Data!$F$2:$F$307,Raw_Data!$J$2:$J$307,H28,Raw_Data!$O$2:$O$307,"H&H",Raw_Data!$N$2:$N$307,"Yes"),SUMIFS(Raw_Data!$F$2:$F$307,Raw_Data!$J$2:$J$307,H28,Raw_Data!$O$2:$O$307,"H&H",Raw_Data!$N$2:$N$307,"Yes",Raw_Data!$C$2:$C$307,$B$3)) -> 3 | J28: =IF($B$3="All countries",SUMIFS(Raw_Data!$P$2:$P$307,Raw_Data!$J$2:$J$307,H28,Raw_Data!$O$2:$O$307,"H&H",Raw_Data!$N$2:$N$307,"Yes"),SUMIFS(Raw_Data!$P$2:$P$307,Raw_Data!$J$2:$J$307,H28,Raw_Data!$O$2:$O$307,"H&H",Raw_Data!$N$2:$N$307,"Yes",Raw_Data!$C$2:$C$307,$B$3))/1000 -> 71.387 | K28: =IF(I28>0,RANK(I28,$I$6:$I$36)+COUNTIF($I$6:I28,I28)-1,"") -> 13
H29: Maquinaria Andina S.A.S. | I29: =IF($B$3="All countries",SUMIFS(Raw_Data!$F$2:$F$307,Raw_Data!$J$2:$J$307,H29,Raw_Data!$O$2:$O$307,"H&H",Raw_Data!$N$2:$N$307,"Yes"),SUMIFS(Raw_Data!$F$2:$F$307,Raw_Data!$J$2:$J$307,H29,Raw_Data!$O$2:$O$307,"H&H",Raw_Data!$N$2:$N$307,"Yes",Raw_Data!$C$2:$C$307,$B$3)) -> 3 | J29: =IF($B$3="All countries",SUMIFS(Raw_Data!$P$2:$P$307,Raw_Data!$J$2:$J$307,H29,Raw_Data!$O$2:$O$307,"H&H",Raw_Data!$N$2:$N$307,"Yes"),SUMIFS(Raw_Data!$P$2:$P$307,Raw_Data!$J$2:$J$307,H29,Raw_Data!$O$2:$O$307,"H&H",Raw_Data!$N$2:$N$307,"Yes",Raw_Data!$C$2:$C$307,$B$3))/1000 -> 147.091 | K29: =IF(I29>0,RANK(I29,$I$6:$I$36)+COUNTIF($I$6:I29,I29)-1,"") -> 14
